
---------------------------------- Compilers -----------------------------------
   aocc/3.1.0 (D)    gcc/11.2.0     (D)    nvhpc_sdk/2021.213
   aocc/3.2.0        gcc/13.2.0            nvhpc_sdk/2022.229
   gcc/10.3.0        intel/2022.1.2 (m)    nvhpc_sdk/2023.233 (D)

--------------------------- Independent Applications ---------------------------
   R/3.6.3                        mambaforge/23.1.0-1
   R/4.2.2                        mathematica/9.0
   R/4.4.0               (D)      mathematica/11.1.0   (D)
   allinea/6.0.4         (m)      matlab/R2018b
   anaconda/2020.11               matlab/R2019b
   anaconda/2022.10               matlab/R2020b
   anaconda/2023.09      (D)      matlab/R2021b        (D)
   antlr/4.13.1                   matlab/R2022b
   arm-forge/19.1.3      (m)      matlab/R2023b
   autotools/2.69                 maven/3.8.1
   autotools/2.71        (D)      ncl/6.3.0
   chimerax/1.2.5                 nco/4.8.1
   clustershell/1.9.2             papi/5.4.3
   cmake/3.5.2                    papi/5.5.1           (D)
   cmake/3.9.2                    paraview/5.0.1
   cmake/3.14.1                   paraview/5.6.0
   cmake/3.20.2                   paraview/5.9.0
   cmake/3.25.0                   paraview/5.10.0      (D)
   cmake/3.27.7          (D)      pdtoolkit/3.22
   cube/3.4.3                     pdtoolkit/3.25.1     (D)
   cube/4.3.4            (D)      perl/5.16.3
   cuda/11.2             (g)      perl/5.24.0          (D)
   cuda/11.3             (g)      perl/5.28.1
   cuda/11.4             (g)      perl/5.36.0
   cuda/11.8             (g)      pigz/2.7
   cuda/12.1.1           (g,D)    python/2.7.18
   cudnn/8.1             (g)      python/3.10.2        (D)
   cudnn/8.2             (g)      qt/5.6.0
   cudnn/8.6             (g,D)    qt/5.9.1
   curc-quota/latest              qt/5.15              (D)
   dmtcp/2.6.0                    rclone/1.58.0
   eigen/3.4.0                    rhel7for8/1.0
   emacs/25.3                     rocm/5.2.3           (g)
   emacs/27.2            (D)      rocm/5.3.0           (g)
   expat/2.1.1                    rocm/5.5.0           (g)
   expat/2.3.0           (D)      rocm/5.6.0           (g,D)
   ffmpeg/4.4                     ruby/2.3.1
   gdb/8.1                        ruby/3.0.0           (D)
   gdb/10.1              (D)      singularity/3.6.4    (D)
   ghostscript/9.56.0             singularity/3.7.4
   git-lfs/3.1.2                  slurmtools/0.0.1
   git/2.31.0                     spack/0.20.1
   gmsh/2.16.0                    subversion/1.8.16
   gmsh/4.11.1           (D)      subversion/1.10.2
   gnu_parallel/20160622          subversion/1.14.1    (D)
   gnu_parallel/20210322 (D)      tcltk/8.6.5
   gnuplot/5.4.3                  tcltk/8.6.11         (D)
   idl/8.7                        tdom/0.8.3
   imagemagick/6.9.12             tdom/0.9.2           (D)
   jdk/1.7.0                      texlive/2021
   jdk/1.8.0_91                   totalview/2016.06.21
   jdk/1.8.0_281                  ucx/1.10.1
   jdk/1.8.0                      ucx/1.12.1           (D)
   jdk/18.0.1.1          (D)      udunits/2.2.20
   julia/0.6.2                    udunits/2.2.24
   julia/1.6.0                    udunits/2.2.25
   julia/1.6.6                    udunits/2.2.28       (D)
   julia/1.8.1                    valgrind/3.11.0
   julia/1.9.4                    valgrind/3.17.0      (D)
   julia/1.10.0                   vapor/3.9.1
   julia/1.10.2          (D)      vtf3/1.43
   lftp/4.8.4                     zip/rhel7
   loadbalance/0.2

-------------------------------- Bioinformatics --------------------------------
   alphafold/2.2.0         cutadapt/4.2            plink2/2.00a2.3
   alphafold/2.3.1  (D)    fastqc/0.11.9           qiime2/2023.5
   bamtools/2.5.2          gatk/4.3.0.0            qiime2/2024.2_amplicon (D)
   bbtools/39.01           homer/4.11              samtools/1.16.1
   bcftools/1.16           htslib/1.16             sra-toolkit/3.0.0
   bedtools/2.29.1         multiqc/1.14            star/2.7.10b
   bowtie2/2.5.0           nextflow/22.10.6        trimmomatic/0.39
   bwa/0.7.17              nextflow/23.04   (D)
   cellranger/7.1.0        picard/2.27.5

---------------------------- Lmod Internal Modules -----------------------------
   StdEnv    lmod    settarg

--------------------------------- CU Licensed ----------------------------------
   CST/2021                 ansys/AnsysEM22.2              (D)
   abaqus/V6R2019x          ansys/AnsysEM23.1
   altairfeko/2019.2        coreform/Coreform-Cubit-2021.5
   altairfeko/2023.1 (D)    gaussian/g16_c.02
   ams/2023.101             gridpro/8.2
   ansys/AnsysEM21.2        trelis/16.3.6

  Where:
   D:  Default Module
   g:  built for GPU
   m:  built for host and native MIC

If the avail list is too long consider trying:

"module --default avail" or "ml -d av" to just list the default modules.
"module overview" or "ml ov" to display the number of modules for each name.

Use "module spider" to find all possible modules and extensions.
Use "module keyword key1 key2 ..." to search for all possible modules matching
any of the "keys".


Warning: Cannot perform Hydrogen sampling with GPU-Omega: GPU-Omega disabled.
Traceback (most recent call last):
  File "/projects/bamo6610/software/anaconda/env/openff-sage/lib/python3.9/multiprocessing/process.py", line 315, in _bootstrap
    self.run()
  File "/projects/bamo6610/software/anaconda/env/openff-sage/lib/python3.9/multiprocessing/process.py", line 108, in run
    self._target(*self._args, **self._kwargs)
  File "/projects/bamo6610/software/anaconda/env/openff-sage/lib/python3.9/multiprocessing/managers.py", line 591, in _run_server
    server.serve_forever()
  File "/projects/bamo6610/software/anaconda/env/openff-sage/lib/python3.9/multiprocessing/managers.py", line 184, in serve_forever
    sys.exit(0)
SystemExit: 0

During handling of the above exception, another exception occurred:

Traceback (most recent call last):
  File "/projects/bamo6610/software/anaconda/env/openff-sage/lib/python3.9/multiprocessing/util.py", line 300, in _run_finalizers
    finalizer()
  File "/projects/bamo6610/software/anaconda/env/openff-sage/lib/python3.9/multiprocessing/util.py", line 224, in __call__
    res = self._callback(*self._args, **self._kwargs)
  File "/projects/bamo6610/software/anaconda/env/openff-sage/lib/python3.9/multiprocessing/util.py", line 133, in _remove_temp_dir
    rmtree(tempdir)
  File "/projects/bamo6610/software/anaconda/env/openff-sage/lib/python3.9/shutil.py", line 734, in rmtree
    _rmtree_safe_fd(fd, path, onerror)
  File "/projects/bamo6610/software/anaconda/env/openff-sage/lib/python3.9/shutil.py", line 690, in _rmtree_safe_fd
    onerror(os.unlink, fullname, sys.exc_info())
  File "/projects/bamo6610/software/anaconda/env/openff-sage/lib/python3.9/shutil.py", line 688, in _rmtree_safe_fd
    os.unlink(entry.name, dir_fd=topfd)
OSError: [Errno 16] Device or resource busy: '.nfs00000000027ce568000009e4'
Traceback (most recent call last):
  File "/projects/bamo6610/software/anaconda/env/openff-sage/lib/python3.9/multiprocessing/process.py", line 315, in _bootstrap
    self.run()
  File "/projects/bamo6610/software/anaconda/env/openff-sage/lib/python3.9/multiprocessing/process.py", line 108, in run
    self._target(*self._args, **self._kwargs)
  File "/projects/bamo6610/software/anaconda/env/openff-sage/lib/python3.9/multiprocessing/managers.py", line 591, in _run_server
    server.serve_forever()
  File "/projects/bamo6610/software/anaconda/env/openff-sage/lib/python3.9/multiprocessing/managers.py", line 184, in serve_forever
    sys.exit(0)
SystemExit: 0

During handling of the above exception, another exception occurred:

Traceback (most recent call last):
  File "/projects/bamo6610/software/anaconda/env/openff-sage/lib/python3.9/multiprocessing/util.py", line 300, in _run_finalizers
    finalizer()
  File "/projects/bamo6610/software/anaconda/env/openff-sage/lib/python3.9/multiprocessing/util.py", line 224, in __call__
    res = self._callback(*self._args, **self._kwargs)
  File "/projects/bamo6610/software/anaconda/env/openff-sage/lib/python3.9/multiprocessing/util.py", line 133, in _remove_temp_dir
    rmtree(tempdir)
  File "/projects/bamo6610/software/anaconda/env/openff-sage/lib/python3.9/shutil.py", line 734, in rmtree
    _rmtree_safe_fd(fd, path, onerror)
  File "/projects/bamo6610/software/anaconda/env/openff-sage/lib/python3.9/shutil.py", line 690, in _rmtree_safe_fd
    onerror(os.unlink, fullname, sys.exc_info())
  File "/projects/bamo6610/software/anaconda/env/openff-sage/lib/python3.9/shutil.py", line 688, in _rmtree_safe_fd
    os.unlink(entry.name, dir_fd=topfd)
OSError: [Errno 16] Device or resource busy: '.nfs00000000030d31e5000009e5'
Warning: Cannot perform Hydrogen sampling with GPU-Omega: GPU-Omega disabled.
Traceback (most recent call last):
  File "/projects/bamo6610/software/anaconda/env/openff-sage/lib/python3.9/multiprocessing/process.py", line 315, in _bootstrap
    self.run()
  File "/projects/bamo6610/software/anaconda/env/openff-sage/lib/python3.9/multiprocessing/process.py", line 108, in run
    self._target(*self._args, **self._kwargs)
  File "/projects/bamo6610/software/anaconda/env/openff-sage/lib/python3.9/multiprocessing/managers.py", line 591, in _run_server
    server.serve_forever()
  File "/projects/bamo6610/software/anaconda/env/openff-sage/lib/python3.9/multiprocessing/managers.py", line 184, in serve_forever
    sys.exit(0)
SystemExit: 0

During handling of the above exception, another exception occurred:

Traceback (most recent call last):
  File "/projects/bamo6610/software/anaconda/env/openff-sage/lib/python3.9/multiprocessing/util.py", line 300, in _run_finalizers
    finalizer()
  File "/projects/bamo6610/software/anaconda/env/openff-sage/lib/python3.9/multiprocessing/util.py", line 224, in __call__
    res = self._callback(*self._args, **self._kwargs)
  File "/projects/bamo6610/software/anaconda/env/openff-sage/lib/python3.9/multiprocessing/util.py", line 133, in _remove_temp_dir
    rmtree(tempdir)
  File "/projects/bamo6610/software/anaconda/env/openff-sage/lib/python3.9/shutil.py", line 734, in rmtree
    _rmtree_safe_fd(fd, path, onerror)
  File "/projects/bamo6610/software/anaconda/env/openff-sage/lib/python3.9/shutil.py", line 690, in _rmtree_safe_fd
    onerror(os.unlink, fullname, sys.exc_info())
  File "/projects/bamo6610/software/anaconda/env/openff-sage/lib/python3.9/shutil.py", line 688, in _rmtree_safe_fd
    os.unlink(entry.name, dir_fd=topfd)
OSError: [Errno 16] Device or resource busy: '.nfs00000000027ce579000009e6'
Warning: Cannot perform Hydrogen sampling with GPU-Omega: GPU-Omega disabled.
Traceback (most recent call last):
  File "/projects/bamo6610/software/anaconda/env/openff-sage/lib/python3.9/multiprocessing/process.py", line 315, in _bootstrap
    self.run()
  File "/projects/bamo6610/software/anaconda/env/openff-sage/lib/python3.9/multiprocessing/process.py", line 108, in run
    self._target(*self._args, **self._kwargs)
  File "/projects/bamo6610/software/anaconda/env/openff-sage/lib/python3.9/multiprocessing/managers.py", line 591, in _run_server
    server.serve_forever()
  File "/projects/bamo6610/software/anaconda/env/openff-sage/lib/python3.9/multiprocessing/managers.py", line 184, in serve_forever
    sys.exit(0)
SystemExit: 0

During handling of the above exception, another exception occurred:

Traceback (most recent call last):
  File "/projects/bamo6610/software/anaconda/env/openff-sage/lib/python3.9/multiprocessing/util.py", line 300, in _run_finalizers
    finalizer()
  File "/projects/bamo6610/software/anaconda/env/openff-sage/lib/python3.9/multiprocessing/util.py", line 224, in __call__
    res = self._callback(*self._args, **self._kwargs)
  File "/projects/bamo6610/software/anaconda/env/openff-sage/lib/python3.9/multiprocessing/util.py", line 133, in _remove_temp_dir
    rmtree(tempdir)
  File "/projects/bamo6610/software/anaconda/env/openff-sage/lib/python3.9/shutil.py", line 734, in rmtree
    _rmtree_safe_fd(fd, path, onerror)
  File "/projects/bamo6610/software/anaconda/env/openff-sage/lib/python3.9/shutil.py", line 690, in _rmtree_safe_fd
    onerror(os.unlink, fullname, sys.exc_info())
  File "/projects/bamo6610/software/anaconda/env/openff-sage/lib/python3.9/shutil.py", line 688, in _rmtree_safe_fd
    os.unlink(entry.name, dir_fd=topfd)
OSError: [Errno 16] Device or resource busy: '.nfs00000000031d3a1c000009e7'
Traceback (most recent call last):
  File "/projects/bamo6610/software/anaconda/env/openff-sage/lib/python3.9/multiprocessing/process.py", line 315, in _bootstrap
    self.run()
  File "/projects/bamo6610/software/anaconda/env/openff-sage/lib/python3.9/multiprocessing/process.py", line 108, in run
    self._target(*self._args, **self._kwargs)
  File "/projects/bamo6610/software/anaconda/env/openff-sage/lib/python3.9/multiprocessing/managers.py", line 591, in _run_server
    server.serve_forever()
  File "/projects/bamo6610/software/anaconda/env/openff-sage/lib/python3.9/multiprocessing/managers.py", line 184, in serve_forever
    sys.exit(0)
SystemExit: 0

During handling of the above exception, another exception occurred:

Traceback (most recent call last):
  File "/projects/bamo6610/software/anaconda/env/openff-sage/lib/python3.9/multiprocessing/util.py", line 300, in _run_finalizers
    finalizer()
  File "/projects/bamo6610/software/anaconda/env/openff-sage/lib/python3.9/multiprocessing/util.py", line 224, in __call__
    res = self._callback(*self._args, **self._kwargs)
  File "/projects/bamo6610/software/anaconda/env/openff-sage/lib/python3.9/multiprocessing/util.py", line 133, in _remove_temp_dir
    rmtree(tempdir)
  File "/projects/bamo6610/software/anaconda/env/openff-sage/lib/python3.9/shutil.py", line 734, in rmtree
    _rmtree_safe_fd(fd, path, onerror)
  File "/projects/bamo6610/software/anaconda/env/openff-sage/lib/python3.9/shutil.py", line 690, in _rmtree_safe_fd
    onerror(os.unlink, fullname, sys.exc_info())
  File "/projects/bamo6610/software/anaconda/env/openff-sage/lib/python3.9/shutil.py", line 688, in _rmtree_safe_fd
    os.unlink(entry.name, dir_fd=topfd)
OSError: [Errno 16] Device or resource busy: '.nfs00000000027ce579000009e8'
Traceback (most recent call last):
  File "/projects/bamo6610/software/anaconda/env/openff-sage/lib/python3.9/multiprocessing/process.py", line 315, in _bootstrap
    self.run()
  File "/projects/bamo6610/software/anaconda/env/openff-sage/lib/python3.9/multiprocessing/process.py", line 108, in run
    self._target(*self._args, **self._kwargs)
  File "/projects/bamo6610/software/anaconda/env/openff-sage/lib/python3.9/multiprocessing/managers.py", line 591, in _run_server
    server.serve_forever()
  File "/projects/bamo6610/software/anaconda/env/openff-sage/lib/python3.9/multiprocessing/managers.py", line 184, in serve_forever
    sys.exit(0)
SystemExit: 0

During handling of the above exception, another exception occurred:

Traceback (most recent call last):
  File "/projects/bamo6610/software/anaconda/env/openff-sage/lib/python3.9/multiprocessing/util.py", line 300, in _run_finalizers
    finalizer()
  File "/projects/bamo6610/software/anaconda/env/openff-sage/lib/python3.9/multiprocessing/util.py", line 224, in __call__
    res = self._callback(*self._args, **self._kwargs)
  File "/projects/bamo6610/software/anaconda/env/openff-sage/lib/python3.9/multiprocessing/util.py", line 133, in _remove_temp_dir
    rmtree(tempdir)
  File "/projects/bamo6610/software/anaconda/env/openff-sage/lib/python3.9/shutil.py", line 734, in rmtree
    _rmtree_safe_fd(fd, path, onerror)
  File "/projects/bamo6610/software/anaconda/env/openff-sage/lib/python3.9/shutil.py", line 690, in _rmtree_safe_fd
    onerror(os.unlink, fullname, sys.exc_info())
  File "/projects/bamo6610/software/anaconda/env/openff-sage/lib/python3.9/shutil.py", line 688, in _rmtree_safe_fd
    os.unlink(entry.name, dir_fd=topfd)
OSError: [Errno 16] Device or resource busy: '.nfs00000000031d3a31000009e9'
Traceback (most recent call last):
  File "/projects/bamo6610/software/anaconda/env/openff-sage/lib/python3.9/multiprocessing/process.py", line 315, in _bootstrap
    self.run()
  File "/projects/bamo6610/software/anaconda/env/openff-sage/lib/python3.9/multiprocessing/process.py", line 108, in run
    self._target(*self._args, **self._kwargs)
  File "/projects/bamo6610/software/anaconda/env/openff-sage/lib/python3.9/multiprocessing/managers.py", line 591, in _run_server
    server.serve_forever()
  File "/projects/bamo6610/software/anaconda/env/openff-sage/lib/python3.9/multiprocessing/managers.py", line 184, in serve_forever
    sys.exit(0)
SystemExit: 0

During handling of the above exception, another exception occurred:

Traceback (most recent call last):
  File "/projects/bamo6610/software/anaconda/env/openff-sage/lib/python3.9/multiprocessing/util.py", line 300, in _run_finalizers
    finalizer()
  File "/projects/bamo6610/software/anaconda/env/openff-sage/lib/python3.9/multiprocessing/util.py", line 224, in __call__
    res = self._callback(*self._args, **self._kwargs)
  File "/projects/bamo6610/software/anaconda/env/openff-sage/lib/python3.9/multiprocessing/util.py", line 133, in _remove_temp_dir
    rmtree(tempdir)
  File "/projects/bamo6610/software/anaconda/env/openff-sage/lib/python3.9/shutil.py", line 734, in rmtree
    _rmtree_safe_fd(fd, path, onerror)
  File "/projects/bamo6610/software/anaconda/env/openff-sage/lib/python3.9/shutil.py", line 690, in _rmtree_safe_fd
    onerror(os.unlink, fullname, sys.exc_info())
  File "/projects/bamo6610/software/anaconda/env/openff-sage/lib/python3.9/shutil.py", line 688, in _rmtree_safe_fd
    os.unlink(entry.name, dir_fd=topfd)
OSError: [Errno 16] Device or resource busy: '.nfs00000000031d3a32000009ea'
Warning: Cannot perform Hydrogen sampling with GPU-Omega: GPU-Omega disabled.
Traceback (most recent call last):
  File "/projects/bamo6610/software/anaconda/env/openff-sage/lib/python3.9/multiprocessing/process.py", line 315, in _bootstrap
    self.run()
  File "/projects/bamo6610/software/anaconda/env/openff-sage/lib/python3.9/multiprocessing/process.py", line 108, in run
    self._target(*self._args, **self._kwargs)
  File "/projects/bamo6610/software/anaconda/env/openff-sage/lib/python3.9/multiprocessing/managers.py", line 591, in _run_server
    server.serve_forever()
  File "/projects/bamo6610/software/anaconda/env/openff-sage/lib/python3.9/multiprocessing/managers.py", line 184, in serve_forever
    sys.exit(0)
SystemExit: 0

During handling of the above exception, another exception occurred:

Traceback (most recent call last):
  File "/projects/bamo6610/software/anaconda/env/openff-sage/lib/python3.9/multiprocessing/util.py", line 300, in _run_finalizers
    finalizer()
  File "/projects/bamo6610/software/anaconda/env/openff-sage/lib/python3.9/multiprocessing/util.py", line 224, in __call__
    res = self._callback(*self._args, **self._kwargs)
  File "/projects/bamo6610/software/anaconda/env/openff-sage/lib/python3.9/multiprocessing/util.py", line 133, in _remove_temp_dir
    rmtree(tempdir)
  File "/projects/bamo6610/software/anaconda/env/openff-sage/lib/python3.9/shutil.py", line 734, in rmtree
    _rmtree_safe_fd(fd, path, onerror)
  File "/projects/bamo6610/software/anaconda/env/openff-sage/lib/python3.9/shutil.py", line 690, in _rmtree_safe_fd
    onerror(os.unlink, fullname, sys.exc_info())
  File "/projects/bamo6610/software/anaconda/env/openff-sage/lib/python3.9/shutil.py", line 688, in _rmtree_safe_fd
    os.unlink(entry.name, dir_fd=topfd)
OSError: [Errno 16] Device or resource busy: '.nfs0000000002cd0fde000009eb'
Traceback (most recent call last):
  File "/projects/bamo6610/software/anaconda/env/openff-sage/lib/python3.9/multiprocessing/process.py", line 315, in _bootstrap
    self.run()
  File "/projects/bamo6610/software/anaconda/env/openff-sage/lib/python3.9/multiprocessing/process.py", line 108, in run
    self._target(*self._args, **self._kwargs)
  File "/projects/bamo6610/software/anaconda/env/openff-sage/lib/python3.9/multiprocessing/managers.py", line 591, in _run_server
    server.serve_forever()
  File "/projects/bamo6610/software/anaconda/env/openff-sage/lib/python3.9/multiprocessing/managers.py", line 184, in serve_forever
    sys.exit(0)
SystemExit: 0

During handling of the above exception, another exception occurred:

Traceback (most recent call last):
  File "/projects/bamo6610/software/anaconda/env/openff-sage/lib/python3.9/multiprocessing/util.py", line 300, in _run_finalizers
    finalizer()
  File "/projects/bamo6610/software/anaconda/env/openff-sage/lib/python3.9/multiprocessing/util.py", line 224, in __call__
    res = self._callback(*self._args, **self._kwargs)
  File "/projects/bamo6610/software/anaconda/env/openff-sage/lib/python3.9/multiprocessing/util.py", line 133, in _remove_temp_dir
    rmtree(tempdir)
  File "/projects/bamo6610/software/anaconda/env/openff-sage/lib/python3.9/shutil.py", line 734, in rmtree
    _rmtree_safe_fd(fd, path, onerror)
  File "/projects/bamo6610/software/anaconda/env/openff-sage/lib/python3.9/shutil.py", line 690, in _rmtree_safe_fd
    onerror(os.unlink, fullname, sys.exc_info())
  File "/projects/bamo6610/software/anaconda/env/openff-sage/lib/python3.9/shutil.py", line 688, in _rmtree_safe_fd
    os.unlink(entry.name, dir_fd=topfd)
OSError: [Errno 16] Device or resource busy: '.nfs00000000034d53de000009ec'
Warning: Cannot perform Hydrogen sampling with GPU-Omega: GPU-Omega disabled.
Traceback (most recent call last):
  File "/projects/bamo6610/software/anaconda/env/openff-sage/lib/python3.9/multiprocessing/process.py", line 315, in _bootstrap
    self.run()
  File "/projects/bamo6610/software/anaconda/env/openff-sage/lib/python3.9/multiprocessing/process.py", line 108, in run
    self._target(*self._args, **self._kwargs)
  File "/projects/bamo6610/software/anaconda/env/openff-sage/lib/python3.9/multiprocessing/managers.py", line 591, in _run_server
    server.serve_forever()
  File "/projects/bamo6610/software/anaconda/env/openff-sage/lib/python3.9/multiprocessing/managers.py", line 184, in serve_forever
    sys.exit(0)
SystemExit: 0

During handling of the above exception, another exception occurred:

Traceback (most recent call last):
  File "/projects/bamo6610/software/anaconda/env/openff-sage/lib/python3.9/multiprocessing/util.py", line 300, in _run_finalizers
    finalizer()
  File "/projects/bamo6610/software/anaconda/env/openff-sage/lib/python3.9/multiprocessing/util.py", line 224, in __call__
    res = self._callback(*self._args, **self._kwargs)
  File "/projects/bamo6610/software/anaconda/env/openff-sage/lib/python3.9/multiprocessing/util.py", line 133, in _remove_temp_dir
    rmtree(tempdir)
  File "/projects/bamo6610/software/anaconda/env/openff-sage/lib/python3.9/shutil.py", line 734, in rmtree
    _rmtree_safe_fd(fd, path, onerror)
  File "/projects/bamo6610/software/anaconda/env/openff-sage/lib/python3.9/shutil.py", line 690, in _rmtree_safe_fd
    onerror(os.unlink, fullname, sys.exc_info())
  File "/projects/bamo6610/software/anaconda/env/openff-sage/lib/python3.9/shutil.py", line 688, in _rmtree_safe_fd
    os.unlink(entry.name, dir_fd=topfd)
OSError: [Errno 16] Device or resource busy: '.nfs00000000034d53df000009ed'
Warning: Cannot perform Hydrogen sampling with GPU-Omega: GPU-Omega disabled.
Traceback (most recent call last):
  File "/projects/bamo6610/software/anaconda/env/openff-sage/lib/python3.9/multiprocessing/process.py", line 315, in _bootstrap
    self.run()
  File "/projects/bamo6610/software/anaconda/env/openff-sage/lib/python3.9/multiprocessing/process.py", line 108, in run
    self._target(*self._args, **self._kwargs)
  File "/projects/bamo6610/software/anaconda/env/openff-sage/lib/python3.9/multiprocessing/managers.py", line 591, in _run_server
    server.serve_forever()
  File "/projects/bamo6610/software/anaconda/env/openff-sage/lib/python3.9/multiprocessing/managers.py", line 184, in serve_forever
    sys.exit(0)
SystemExit: 0

During handling of the above exception, another exception occurred:

Traceback (most recent call last):
  File "/projects/bamo6610/software/anaconda/env/openff-sage/lib/python3.9/multiprocessing/util.py", line 300, in _run_finalizers
    finalizer()
  File "/projects/bamo6610/software/anaconda/env/openff-sage/lib/python3.9/multiprocessing/util.py", line 224, in __call__
    res = self._callback(*self._args, **self._kwargs)
  File "/projects/bamo6610/software/anaconda/env/openff-sage/lib/python3.9/multiprocessing/util.py", line 133, in _remove_temp_dir
    rmtree(tempdir)
  File "/projects/bamo6610/software/anaconda/env/openff-sage/lib/python3.9/shutil.py", line 734, in rmtree
    _rmtree_safe_fd(fd, path, onerror)
  File "/projects/bamo6610/software/anaconda/env/openff-sage/lib/python3.9/shutil.py", line 690, in _rmtree_safe_fd
    onerror(os.unlink, fullname, sys.exc_info())
  File "/projects/bamo6610/software/anaconda/env/openff-sage/lib/python3.9/shutil.py", line 688, in _rmtree_safe_fd
    os.unlink(entry.name, dir_fd=topfd)
OSError: [Errno 16] Device or resource busy: '.nfs00000000034d53ef000009ee'
Traceback (most recent call last):
  File "/projects/bamo6610/software/anaconda/env/openff-sage/lib/python3.9/multiprocessing/process.py", line 315, in _bootstrap
    self.run()
  File "/projects/bamo6610/software/anaconda/env/openff-sage/lib/python3.9/multiprocessing/process.py", line 108, in run
    self._target(*self._args, **self._kwargs)
  File "/projects/bamo6610/software/anaconda/env/openff-sage/lib/python3.9/multiprocessing/managers.py", line 591, in _run_server
    server.serve_forever()
  File "/projects/bamo6610/software/anaconda/env/openff-sage/lib/python3.9/multiprocessing/managers.py", line 184, in serve_forever
    sys.exit(0)
SystemExit: 0

During handling of the above exception, another exception occurred:

Traceback (most recent call last):
  File "/projects/bamo6610/software/anaconda/env/openff-sage/lib/python3.9/multiprocessing/util.py", line 300, in _run_finalizers
    finalizer()
  File "/projects/bamo6610/software/anaconda/env/openff-sage/lib/python3.9/multiprocessing/util.py", line 224, in __call__
    res = self._callback(*self._args, **self._kwargs)
  File "/projects/bamo6610/software/anaconda/env/openff-sage/lib/python3.9/multiprocessing/util.py", line 133, in _remove_temp_dir
    rmtree(tempdir)
  File "/projects/bamo6610/software/anaconda/env/openff-sage/lib/python3.9/shutil.py", line 734, in rmtree
    _rmtree_safe_fd(fd, path, onerror)
  File "/projects/bamo6610/software/anaconda/env/openff-sage/lib/python3.9/shutil.py", line 690, in _rmtree_safe_fd
    onerror(os.unlink, fullname, sys.exc_info())
  File "/projects/bamo6610/software/anaconda/env/openff-sage/lib/python3.9/shutil.py", line 688, in _rmtree_safe_fd
    os.unlink(entry.name, dir_fd=topfd)
OSError: [Errno 16] Device or resource busy: '.nfs00000000029cf650000009ef'
Warning: Cannot perform Hydrogen sampling with GPU-Omega: GPU-Omega disabled.
Traceback (most recent call last):
  File "/projects/bamo6610/software/anaconda/env/openff-sage/lib/python3.9/multiprocessing/process.py", line 315, in _bootstrap
    self.run()
  File "/projects/bamo6610/software/anaconda/env/openff-sage/lib/python3.9/multiprocessing/process.py", line 108, in run
    self._target(*self._args, **self._kwargs)
  File "/projects/bamo6610/software/anaconda/env/openff-sage/lib/python3.9/multiprocessing/managers.py", line 591, in _run_server
    server.serve_forever()
  File "/projects/bamo6610/software/anaconda/env/openff-sage/lib/python3.9/multiprocessing/managers.py", line 184, in serve_forever
    sys.exit(0)
SystemExit: 0

During handling of the above exception, another exception occurred:

Traceback (most recent call last):
  File "/projects/bamo6610/software/anaconda/env/openff-sage/lib/python3.9/multiprocessing/util.py", line 300, in _run_finalizers
    finalizer()
  File "/projects/bamo6610/software/anaconda/env/openff-sage/lib/python3.9/multiprocessing/util.py", line 224, in __call__
    res = self._callback(*self._args, **self._kwargs)
  File "/projects/bamo6610/software/anaconda/env/openff-sage/lib/python3.9/multiprocessing/util.py", line 133, in _remove_temp_dir
    rmtree(tempdir)
  File "/projects/bamo6610/software/anaconda/env/openff-sage/lib/python3.9/shutil.py", line 734, in rmtree
    _rmtree_safe_fd(fd, path, onerror)
  File "/projects/bamo6610/software/anaconda/env/openff-sage/lib/python3.9/shutil.py", line 690, in _rmtree_safe_fd
    onerror(os.unlink, fullname, sys.exc_info())
  File "/projects/bamo6610/software/anaconda/env/openff-sage/lib/python3.9/shutil.py", line 688, in _rmtree_safe_fd
    os.unlink(entry.name, dir_fd=topfd)
OSError: [Errno 16] Device or resource busy: '.nfs00000000035d5c01000009f0'
Traceback (most recent call last):
  File "/projects/bamo6610/software/anaconda/env/openff-sage/lib/python3.9/multiprocessing/process.py", line 315, in _bootstrap
    self.run()
  File "/projects/bamo6610/software/anaconda/env/openff-sage/lib/python3.9/multiprocessing/process.py", line 108, in run
    self._target(*self._args, **self._kwargs)
  File "/projects/bamo6610/software/anaconda/env/openff-sage/lib/python3.9/multiprocessing/managers.py", line 591, in _run_server
    server.serve_forever()
  File "/projects/bamo6610/software/anaconda/env/openff-sage/lib/python3.9/multiprocessing/managers.py", line 184, in serve_forever
    sys.exit(0)
SystemExit: 0

During handling of the above exception, another exception occurred:

Traceback (most recent call last):
  File "/projects/bamo6610/software/anaconda/env/openff-sage/lib/python3.9/multiprocessing/util.py", line 300, in _run_finalizers
    finalizer()
  File "/projects/bamo6610/software/anaconda/env/openff-sage/lib/python3.9/multiprocessing/util.py", line 224, in __call__
    res = self._callback(*self._args, **self._kwargs)
  File "/projects/bamo6610/software/anaconda/env/openff-sage/lib/python3.9/multiprocessing/util.py", line 133, in _remove_temp_dir
    rmtree(tempdir)
  File "/projects/bamo6610/software/anaconda/env/openff-sage/lib/python3.9/shutil.py", line 734, in rmtree
    _rmtree_safe_fd(fd, path, onerror)
  File "/projects/bamo6610/software/anaconda/env/openff-sage/lib/python3.9/shutil.py", line 690, in _rmtree_safe_fd
    onerror(os.unlink, fullname, sys.exc_info())
  File "/projects/bamo6610/software/anaconda/env/openff-sage/lib/python3.9/shutil.py", line 688, in _rmtree_safe_fd
    os.unlink(entry.name, dir_fd=topfd)
OSError: [Errno 16] Device or resource busy: '.nfs00000000035d5c06000009f1'
Traceback (most recent call last):
  File "/projects/bamo6610/software/anaconda/env/openff-sage/lib/python3.9/multiprocessing/process.py", line 315, in _bootstrap
    self.run()
  File "/projects/bamo6610/software/anaconda/env/openff-sage/lib/python3.9/multiprocessing/process.py", line 108, in run
    self._target(*self._args, **self._kwargs)
  File "/projects/bamo6610/software/anaconda/env/openff-sage/lib/python3.9/multiprocessing/managers.py", line 591, in _run_server
    server.serve_forever()
  File "/projects/bamo6610/software/anaconda/env/openff-sage/lib/python3.9/multiprocessing/managers.py", line 184, in serve_forever
    sys.exit(0)
SystemExit: 0

During handling of the above exception, another exception occurred:

Traceback (most recent call last):
  File "/projects/bamo6610/software/anaconda/env/openff-sage/lib/python3.9/multiprocessing/util.py", line 300, in _run_finalizers
    finalizer()
  File "/projects/bamo6610/software/anaconda/env/openff-sage/lib/python3.9/multiprocessing/util.py", line 224, in __call__
    res = self._callback(*self._args, **self._kwargs)
  File "/projects/bamo6610/software/anaconda/env/openff-sage/lib/python3.9/multiprocessing/util.py", line 133, in _remove_temp_dir
    rmtree(tempdir)
  File "/projects/bamo6610/software/anaconda/env/openff-sage/lib/python3.9/shutil.py", line 734, in rmtree
    _rmtree_safe_fd(fd, path, onerror)
  File "/projects/bamo6610/software/anaconda/env/openff-sage/lib/python3.9/shutil.py", line 690, in _rmtree_safe_fd
    onerror(os.unlink, fullname, sys.exc_info())
  File "/projects/bamo6610/software/anaconda/env/openff-sage/lib/python3.9/shutil.py", line 688, in _rmtree_safe_fd
    os.unlink(entry.name, dir_fd=topfd)
OSError: [Errno 16] Device or resource busy: '.nfs00000000035d5c7f000009f2'
Warning: Cannot perform Hydrogen sampling with GPU-Omega: GPU-Omega disabled.
Traceback (most recent call last):
  File "/projects/bamo6610/software/anaconda/env/openff-sage/lib/python3.9/multiprocessing/process.py", line 315, in _bootstrap
    self.run()
  File "/projects/bamo6610/software/anaconda/env/openff-sage/lib/python3.9/multiprocessing/process.py", line 108, in run
    self._target(*self._args, **self._kwargs)
  File "/projects/bamo6610/software/anaconda/env/openff-sage/lib/python3.9/multiprocessing/managers.py", line 591, in _run_server
    server.serve_forever()
  File "/projects/bamo6610/software/anaconda/env/openff-sage/lib/python3.9/multiprocessing/managers.py", line 184, in serve_forever
    sys.exit(0)
SystemExit: 0

During handling of the above exception, another exception occurred:

Traceback (most recent call last):
  File "/projects/bamo6610/software/anaconda/env/openff-sage/lib/python3.9/multiprocessing/util.py", line 300, in _run_finalizers
    finalizer()
  File "/projects/bamo6610/software/anaconda/env/openff-sage/lib/python3.9/multiprocessing/util.py", line 224, in __call__
    res = self._callback(*self._args, **self._kwargs)
  File "/projects/bamo6610/software/anaconda/env/openff-sage/lib/python3.9/multiprocessing/util.py", line 133, in _remove_temp_dir
    rmtree(tempdir)
  File "/projects/bamo6610/software/anaconda/env/openff-sage/lib/python3.9/shutil.py", line 734, in rmtree
    _rmtree_safe_fd(fd, path, onerror)
  File "/projects/bamo6610/software/anaconda/env/openff-sage/lib/python3.9/shutil.py", line 690, in _rmtree_safe_fd
    onerror(os.unlink, fullname, sys.exc_info())
  File "/projects/bamo6610/software/anaconda/env/openff-sage/lib/python3.9/shutil.py", line 688, in _rmtree_safe_fd
    os.unlink(entry.name, dir_fd=topfd)
OSError: [Errno 16] Device or resource busy: '.nfs00000000036d6481000009f3'
Traceback (most recent call last):
  File "/projects/bamo6610/software/anaconda/env/openff-sage/lib/python3.9/multiprocessing/process.py", line 315, in _bootstrap
    self.run()
  File "/projects/bamo6610/software/anaconda/env/openff-sage/lib/python3.9/multiprocessing/process.py", line 108, in run
    self._target(*self._args, **self._kwargs)
  File "/projects/bamo6610/software/anaconda/env/openff-sage/lib/python3.9/multiprocessing/managers.py", line 591, in _run_server
    server.serve_forever()
  File "/projects/bamo6610/software/anaconda/env/openff-sage/lib/python3.9/multiprocessing/managers.py", line 184, in serve_forever
    sys.exit(0)
SystemExit: 0

During handling of the above exception, another exception occurred:

Traceback (most recent call last):
  File "/projects/bamo6610/software/anaconda/env/openff-sage/lib/python3.9/multiprocessing/util.py", line 300, in _run_finalizers
    finalizer()
  File "/projects/bamo6610/software/anaconda/env/openff-sage/lib/python3.9/multiprocessing/util.py", line 224, in __call__
    res = self._callback(*self._args, **self._kwargs)
  File "/projects/bamo6610/software/anaconda/env/openff-sage/lib/python3.9/multiprocessing/util.py", line 133, in _remove_temp_dir
    rmtree(tempdir)
  File "/projects/bamo6610/software/anaconda/env/openff-sage/lib/python3.9/shutil.py", line 734, in rmtree
    _rmtree_safe_fd(fd, path, onerror)
  File "/projects/bamo6610/software/anaconda/env/openff-sage/lib/python3.9/shutil.py", line 690, in _rmtree_safe_fd
    onerror(os.unlink, fullname, sys.exc_info())
  File "/projects/bamo6610/software/anaconda/env/openff-sage/lib/python3.9/shutil.py", line 688, in _rmtree_safe_fd
    os.unlink(entry.name, dir_fd=topfd)
OSError: [Errno 16] Device or resource busy: '.nfs00000000036d6493000009f4'
Warning: Cannot perform Hydrogen sampling with GPU-Omega: GPU-Omega disabled.
Traceback (most recent call last):
  File "/projects/bamo6610/software/anaconda/env/openff-sage/lib/python3.9/multiprocessing/process.py", line 315, in _bootstrap
    self.run()
  File "/projects/bamo6610/software/anaconda/env/openff-sage/lib/python3.9/multiprocessing/process.py", line 108, in run
    self._target(*self._args, **self._kwargs)
  File "/projects/bamo6610/software/anaconda/env/openff-sage/lib/python3.9/multiprocessing/managers.py", line 591, in _run_server
    server.serve_forever()
  File "/projects/bamo6610/software/anaconda/env/openff-sage/lib/python3.9/multiprocessing/managers.py", line 184, in serve_forever
    sys.exit(0)
SystemExit: 0

During handling of the above exception, another exception occurred:

Traceback (most recent call last):
  File "/projects/bamo6610/software/anaconda/env/openff-sage/lib/python3.9/multiprocessing/util.py", line 300, in _run_finalizers
    finalizer()
  File "/projects/bamo6610/software/anaconda/env/openff-sage/lib/python3.9/multiprocessing/util.py", line 224, in __call__
    res = self._callback(*self._args, **self._kwargs)
  File "/projects/bamo6610/software/anaconda/env/openff-sage/lib/python3.9/multiprocessing/util.py", line 133, in _remove_temp_dir
    rmtree(tempdir)
  File "/projects/bamo6610/software/anaconda/env/openff-sage/lib/python3.9/shutil.py", line 734, in rmtree
    _rmtree_safe_fd(fd, path, onerror)
  File "/projects/bamo6610/software/anaconda/env/openff-sage/lib/python3.9/shutil.py", line 690, in _rmtree_safe_fd
    onerror(os.unlink, fullname, sys.exc_info())
  File "/projects/bamo6610/software/anaconda/env/openff-sage/lib/python3.9/shutil.py", line 688, in _rmtree_safe_fd
    os.unlink(entry.name, dir_fd=topfd)
OSError: [Errno 16] Device or resource busy: '.nfs00000000036d6495000009f5'
Warning: Cannot perform Hydrogen sampling with GPU-Omega: GPU-Omega disabled.
Traceback (most recent call last):
  File "/projects/bamo6610/software/anaconda/env/openff-sage/lib/python3.9/multiprocessing/process.py", line 315, in _bootstrap
    self.run()
  File "/projects/bamo6610/software/anaconda/env/openff-sage/lib/python3.9/multiprocessing/process.py", line 108, in run
    self._target(*self._args, **self._kwargs)
  File "/projects/bamo6610/software/anaconda/env/openff-sage/lib/python3.9/multiprocessing/managers.py", line 591, in _run_server
    server.serve_forever()
  File "/projects/bamo6610/software/anaconda/env/openff-sage/lib/python3.9/multiprocessing/managers.py", line 184, in serve_forever
    sys.exit(0)
SystemExit: 0

During handling of the above exception, another exception occurred:

Traceback (most recent call last):
  File "/projects/bamo6610/software/anaconda/env/openff-sage/lib/python3.9/multiprocessing/util.py", line 300, in _run_finalizers
    finalizer()
  File "/projects/bamo6610/software/anaconda/env/openff-sage/lib/python3.9/multiprocessing/util.py", line 224, in __call__
    res = self._callback(*self._args, **self._kwargs)
  File "/projects/bamo6610/software/anaconda/env/openff-sage/lib/python3.9/multiprocessing/util.py", line 133, in _remove_temp_dir
    rmtree(tempdir)
  File "/projects/bamo6610/software/anaconda/env/openff-sage/lib/python3.9/shutil.py", line 734, in rmtree
    _rmtree_safe_fd(fd, path, onerror)
  File "/projects/bamo6610/software/anaconda/env/openff-sage/lib/python3.9/shutil.py", line 690, in _rmtree_safe_fd
    onerror(os.unlink, fullname, sys.exc_info())
  File "/projects/bamo6610/software/anaconda/env/openff-sage/lib/python3.9/shutil.py", line 688, in _rmtree_safe_fd
    os.unlink(entry.name, dir_fd=topfd)
OSError: [Errno 16] Device or resource busy: '.nfs00000000036d64a7000009f6'
Traceback (most recent call last):
  File "/projects/bamo6610/software/anaconda/env/openff-sage/lib/python3.9/multiprocessing/process.py", line 315, in _bootstrap
    self.run()
  File "/projects/bamo6610/software/anaconda/env/openff-sage/lib/python3.9/multiprocessing/process.py", line 108, in run
    self._target(*self._args, **self._kwargs)
  File "/projects/bamo6610/software/anaconda/env/openff-sage/lib/python3.9/multiprocessing/managers.py", line 591, in _run_server
    server.serve_forever()
  File "/projects/bamo6610/software/anaconda/env/openff-sage/lib/python3.9/multiprocessing/managers.py", line 184, in serve_forever
    sys.exit(0)
SystemExit: 0

During handling of the above exception, another exception occurred:

Traceback (most recent call last):
  File "/projects/bamo6610/software/anaconda/env/openff-sage/lib/python3.9/multiprocessing/util.py", line 300, in _run_finalizers
    finalizer()
  File "/projects/bamo6610/software/anaconda/env/openff-sage/lib/python3.9/multiprocessing/util.py", line 224, in __call__
    res = self._callback(*self._args, **self._kwargs)
  File "/projects/bamo6610/software/anaconda/env/openff-sage/lib/python3.9/multiprocessing/util.py", line 133, in _remove_temp_dir
    rmtree(tempdir)
  File "/projects/bamo6610/software/anaconda/env/openff-sage/lib/python3.9/shutil.py", line 734, in rmtree
    _rmtree_safe_fd(fd, path, onerror)
  File "/projects/bamo6610/software/anaconda/env/openff-sage/lib/python3.9/shutil.py", line 690, in _rmtree_safe_fd
    onerror(os.unlink, fullname, sys.exc_info())
  File "/projects/bamo6610/software/anaconda/env/openff-sage/lib/python3.9/shutil.py", line 688, in _rmtree_safe_fd
    os.unlink(entry.name, dir_fd=topfd)
OSError: [Errno 16] Device or resource busy: '.nfs00000000036d64ab000009f7'
Warning: Cannot perform Hydrogen sampling with GPU-Omega: GPU-Omega disabled.
Traceback (most recent call last):
  File "/projects/bamo6610/software/anaconda/env/openff-sage/lib/python3.9/multiprocessing/process.py", line 315, in _bootstrap
    self.run()
  File "/projects/bamo6610/software/anaconda/env/openff-sage/lib/python3.9/multiprocessing/process.py", line 108, in run
    self._target(*self._args, **self._kwargs)
  File "/projects/bamo6610/software/anaconda/env/openff-sage/lib/python3.9/multiprocessing/managers.py", line 591, in _run_server
    server.serve_forever()
  File "/projects/bamo6610/software/anaconda/env/openff-sage/lib/python3.9/multiprocessing/managers.py", line 184, in serve_forever
    sys.exit(0)
SystemExit: 0

During handling of the above exception, another exception occurred:

Traceback (most recent call last):
  File "/projects/bamo6610/software/anaconda/env/openff-sage/lib/python3.9/multiprocessing/util.py", line 300, in _run_finalizers
    finalizer()
  File "/projects/bamo6610/software/anaconda/env/openff-sage/lib/python3.9/multiprocessing/util.py", line 224, in __call__
    res = self._callback(*self._args, **self._kwargs)
  File "/projects/bamo6610/software/anaconda/env/openff-sage/lib/python3.9/multiprocessing/util.py", line 133, in _remove_temp_dir
    rmtree(tempdir)
  File "/projects/bamo6610/software/anaconda/env/openff-sage/lib/python3.9/shutil.py", line 734, in rmtree
    _rmtree_safe_fd(fd, path, onerror)
  File "/projects/bamo6610/software/anaconda/env/openff-sage/lib/python3.9/shutil.py", line 690, in _rmtree_safe_fd
    onerror(os.unlink, fullname, sys.exc_info())
  File "/projects/bamo6610/software/anaconda/env/openff-sage/lib/python3.9/shutil.py", line 688, in _rmtree_safe_fd
    os.unlink(entry.name, dir_fd=topfd)
OSError: [Errno 16] Device or resource busy: '.nfs00000000036d64c2000009f8'
Traceback (most recent call last):
  File "/projects/bamo6610/software/anaconda/env/openff-sage/lib/python3.9/multiprocessing/process.py", line 315, in _bootstrap
    self.run()
  File "/projects/bamo6610/software/anaconda/env/openff-sage/lib/python3.9/multiprocessing/process.py", line 108, in run
    self._target(*self._args, **self._kwargs)
  File "/projects/bamo6610/software/anaconda/env/openff-sage/lib/python3.9/multiprocessing/managers.py", line 591, in _run_server
    server.serve_forever()
  File "/projects/bamo6610/software/anaconda/env/openff-sage/lib/python3.9/multiprocessing/managers.py", line 184, in serve_forever
    sys.exit(0)
SystemExit: 0

During handling of the above exception, another exception occurred:

Traceback (most recent call last):
  File "/projects/bamo6610/software/anaconda/env/openff-sage/lib/python3.9/multiprocessing/util.py", line 300, in _run_finalizers
    finalizer()
  File "/projects/bamo6610/software/anaconda/env/openff-sage/lib/python3.9/multiprocessing/util.py", line 224, in __call__
    res = self._callback(*self._args, **self._kwargs)
  File "/projects/bamo6610/software/anaconda/env/openff-sage/lib/python3.9/multiprocessing/util.py", line 133, in _remove_temp_dir
    rmtree(tempdir)
  File "/projects/bamo6610/software/anaconda/env/openff-sage/lib/python3.9/shutil.py", line 734, in rmtree
    _rmtree_safe_fd(fd, path, onerror)
  File "/projects/bamo6610/software/anaconda/env/openff-sage/lib/python3.9/shutil.py", line 690, in _rmtree_safe_fd
    onerror(os.unlink, fullname, sys.exc_info())
  File "/projects/bamo6610/software/anaconda/env/openff-sage/lib/python3.9/shutil.py", line 688, in _rmtree_safe_fd
    os.unlink(entry.name, dir_fd=topfd)
OSError: [Errno 16] Device or resource busy: '.nfs00000000036d64c3000009f9'
Traceback (most recent call last):
  File "/projects/bamo6610/software/anaconda/env/openff-sage/lib/python3.9/multiprocessing/process.py", line 315, in _bootstrap
    self.run()
  File "/projects/bamo6610/software/anaconda/env/openff-sage/lib/python3.9/multiprocessing/process.py", line 108, in run
    self._target(*self._args, **self._kwargs)
  File "/projects/bamo6610/software/anaconda/env/openff-sage/lib/python3.9/multiprocessing/managers.py", line 591, in _run_server
    server.serve_forever()
  File "/projects/bamo6610/software/anaconda/env/openff-sage/lib/python3.9/multiprocessing/managers.py", line 184, in serve_forever
    sys.exit(0)
SystemExit: 0

During handling of the above exception, another exception occurred:

Traceback (most recent call last):
  File "/projects/bamo6610/software/anaconda/env/openff-sage/lib/python3.9/multiprocessing/util.py", line 300, in _run_finalizers
    finalizer()
  File "/projects/bamo6610/software/anaconda/env/openff-sage/lib/python3.9/multiprocessing/util.py", line 224, in __call__
    res = self._callback(*self._args, **self._kwargs)
  File "/projects/bamo6610/software/anaconda/env/openff-sage/lib/python3.9/multiprocessing/util.py", line 133, in _remove_temp_dir
    rmtree(tempdir)
  File "/projects/bamo6610/software/anaconda/env/openff-sage/lib/python3.9/shutil.py", line 734, in rmtree
    _rmtree_safe_fd(fd, path, onerror)
  File "/projects/bamo6610/software/anaconda/env/openff-sage/lib/python3.9/shutil.py", line 690, in _rmtree_safe_fd
    onerror(os.unlink, fullname, sys.exc_info())
  File "/projects/bamo6610/software/anaconda/env/openff-sage/lib/python3.9/shutil.py", line 688, in _rmtree_safe_fd
    os.unlink(entry.name, dir_fd=topfd)
OSError: [Errno 16] Device or resource busy: '.nfs00000000036d64d7000009fa'
Warning: importing 'simtk.openmm' is deprecated.  Import 'openmm' instead.
2024-08-09 10:39:11,591: Setting CUDA platform to use precision model 'mixed'.
2024-08-09 10:39:11,650: Reading phase solvent1
2024-08-09 10:39:12,111: WARNING - openmmtools.multistate.multistatesampler - Warning: The openmmtools.multistate API is experimental and may change in future releases
2024-08-09 10:39:12,139: Reading phase solvent2
2024-08-09 10:39:12,150: WARNING - openmmtools.multistate.multistatesampler - Warning: The openmmtools.multistate API is experimental and may change in future releases
2024-08-09 10:39:13,163: Protocol failed to execute: a45bc5e4000a48f0af9613165b959846|run_solvation_yank
2024-08-09 10:39:13,163: Protocol failed to execute: a45bc5e4000a48f0af9613165b959846|conditional_group
Traceback (most recent call last):
  File "/projects/bamo6610/software/anaconda/env/openff-sage/lib/python3.9/multiprocessing/process.py", line 315, in _bootstrap
    self.run()
  File "/projects/bamo6610/software/anaconda/env/openff-sage/lib/python3.9/multiprocessing/process.py", line 108, in run
    self._target(*self._args, **self._kwargs)
  File "/projects/bamo6610/software/anaconda/env/openff-sage/lib/python3.9/multiprocessing/managers.py", line 591, in _run_server
    server.serve_forever()
  File "/projects/bamo6610/software/anaconda/env/openff-sage/lib/python3.9/multiprocessing/managers.py", line 184, in serve_forever
    sys.exit(0)
SystemExit: 0

During handling of the above exception, another exception occurred:

Traceback (most recent call last):
  File "/projects/bamo6610/software/anaconda/env/openff-sage/lib/python3.9/multiprocessing/util.py", line 300, in _run_finalizers
    finalizer()
  File "/projects/bamo6610/software/anaconda/env/openff-sage/lib/python3.9/multiprocessing/util.py", line 224, in __call__
    res = self._callback(*self._args, **self._kwargs)
  File "/projects/bamo6610/software/anaconda/env/openff-sage/lib/python3.9/multiprocessing/util.py", line 133, in _remove_temp_dir
    rmtree(tempdir)
  File "/projects/bamo6610/software/anaconda/env/openff-sage/lib/python3.9/shutil.py", line 734, in rmtree
    _rmtree_safe_fd(fd, path, onerror)
  File "/projects/bamo6610/software/anaconda/env/openff-sage/lib/python3.9/shutil.py", line 690, in _rmtree_safe_fd
    onerror(os.unlink, fullname, sys.exc_info())
  File "/projects/bamo6610/software/anaconda/env/openff-sage/lib/python3.9/shutil.py", line 688, in _rmtree_safe_fd
    os.unlink(entry.name, dir_fd=topfd)
OSError: [Errno 16] Device or resource busy: '.nfs0000000002fd2928000009fb'
Warning: importing 'simtk.openmm' is deprecated.  Import 'openmm' instead.
2024-08-09 10:39:18,223: Setting CUDA platform to use precision model 'mixed'.
2024-08-09 10:39:18,280: Reading phase solvent1
2024-08-09 10:39:18,742: WARNING - openmmtools.multistate.multistatesampler - Warning: The openmmtools.multistate API is experimental and may change in future releases
2024-08-09 10:39:18,772: Reading phase solvent2
2024-08-09 10:39:18,784: WARNING - openmmtools.multistate.multistatesampler - Warning: The openmmtools.multistate API is experimental and may change in future releases
2024-08-09 10:39:19,804: Protocol failed to execute: aa5a4d8d41e44076ad526a4c053a7a4a|run_solvation_yank
2024-08-09 10:39:19,804: Protocol failed to execute: aa5a4d8d41e44076ad526a4c053a7a4a|conditional_group
Traceback (most recent call last):
  File "/projects/bamo6610/software/anaconda/env/openff-sage/lib/python3.9/multiprocessing/process.py", line 315, in _bootstrap
    self.run()
  File "/projects/bamo6610/software/anaconda/env/openff-sage/lib/python3.9/multiprocessing/process.py", line 108, in run
    self._target(*self._args, **self._kwargs)
  File "/projects/bamo6610/software/anaconda/env/openff-sage/lib/python3.9/multiprocessing/managers.py", line 591, in _run_server
    server.serve_forever()
  File "/projects/bamo6610/software/anaconda/env/openff-sage/lib/python3.9/multiprocessing/managers.py", line 184, in serve_forever
    sys.exit(0)
SystemExit: 0

During handling of the above exception, another exception occurred:

Traceback (most recent call last):
  File "/projects/bamo6610/software/anaconda/env/openff-sage/lib/python3.9/multiprocessing/util.py", line 300, in _run_finalizers
    finalizer()
  File "/projects/bamo6610/software/anaconda/env/openff-sage/lib/python3.9/multiprocessing/util.py", line 224, in __call__
    res = self._callback(*self._args, **self._kwargs)
  File "/projects/bamo6610/software/anaconda/env/openff-sage/lib/python3.9/multiprocessing/util.py", line 133, in _remove_temp_dir
    rmtree(tempdir)
  File "/projects/bamo6610/software/anaconda/env/openff-sage/lib/python3.9/shutil.py", line 734, in rmtree
    _rmtree_safe_fd(fd, path, onerror)
  File "/projects/bamo6610/software/anaconda/env/openff-sage/lib/python3.9/shutil.py", line 690, in _rmtree_safe_fd
    onerror(os.unlink, fullname, sys.exc_info())
  File "/projects/bamo6610/software/anaconda/env/openff-sage/lib/python3.9/shutil.py", line 688, in _rmtree_safe_fd
    os.unlink(entry.name, dir_fd=topfd)
OSError: [Errno 16] Device or resource busy: '.nfs00000000037d6d14000009fc'
Traceback (most recent call last):
  File "/projects/bamo6610/software/anaconda/env/openff-sage/lib/python3.9/multiprocessing/process.py", line 315, in _bootstrap
    self.run()
  File "/projects/bamo6610/software/anaconda/env/openff-sage/lib/python3.9/multiprocessing/process.py", line 108, in run
    self._target(*self._args, **self._kwargs)
  File "/projects/bamo6610/software/anaconda/env/openff-sage/lib/python3.9/multiprocessing/managers.py", line 591, in _run_server
    server.serve_forever()
  File "/projects/bamo6610/software/anaconda/env/openff-sage/lib/python3.9/multiprocessing/managers.py", line 184, in serve_forever
    sys.exit(0)
SystemExit: 0

During handling of the above exception, another exception occurred:

Traceback (most recent call last):
  File "/projects/bamo6610/software/anaconda/env/openff-sage/lib/python3.9/multiprocessing/util.py", line 300, in _run_finalizers
    finalizer()
  File "/projects/bamo6610/software/anaconda/env/openff-sage/lib/python3.9/multiprocessing/util.py", line 224, in __call__
    res = self._callback(*self._args, **self._kwargs)
  File "/projects/bamo6610/software/anaconda/env/openff-sage/lib/python3.9/multiprocessing/util.py", line 133, in _remove_temp_dir
    rmtree(tempdir)
  File "/projects/bamo6610/software/anaconda/env/openff-sage/lib/python3.9/shutil.py", line 734, in rmtree
    _rmtree_safe_fd(fd, path, onerror)
  File "/projects/bamo6610/software/anaconda/env/openff-sage/lib/python3.9/shutil.py", line 690, in _rmtree_safe_fd
    onerror(os.unlink, fullname, sys.exc_info())
  File "/projects/bamo6610/software/anaconda/env/openff-sage/lib/python3.9/shutil.py", line 688, in _rmtree_safe_fd
    os.unlink(entry.name, dir_fd=topfd)
OSError: [Errno 16] Device or resource busy: '.nfs00000000037d6d5b000009fd'
Traceback (most recent call last):
  File "/projects/bamo6610/software/anaconda/env/openff-sage/lib/python3.9/multiprocessing/process.py", line 315, in _bootstrap
    self.run()
  File "/projects/bamo6610/software/anaconda/env/openff-sage/lib/python3.9/multiprocessing/process.py", line 108, in run
    self._target(*self._args, **self._kwargs)
  File "/projects/bamo6610/software/anaconda/env/openff-sage/lib/python3.9/multiprocessing/managers.py", line 591, in _run_server
    server.serve_forever()
  File "/projects/bamo6610/software/anaconda/env/openff-sage/lib/python3.9/multiprocessing/managers.py", line 184, in serve_forever
    sys.exit(0)
SystemExit: 0

During handling of the above exception, another exception occurred:

Traceback (most recent call last):
  File "/projects/bamo6610/software/anaconda/env/openff-sage/lib/python3.9/multiprocessing/util.py", line 300, in _run_finalizers
    finalizer()
  File "/projects/bamo6610/software/anaconda/env/openff-sage/lib/python3.9/multiprocessing/util.py", line 224, in __call__
    res = self._callback(*self._args, **self._kwargs)
  File "/projects/bamo6610/software/anaconda/env/openff-sage/lib/python3.9/multiprocessing/util.py", line 133, in _remove_temp_dir
    rmtree(tempdir)
  File "/projects/bamo6610/software/anaconda/env/openff-sage/lib/python3.9/shutil.py", line 734, in rmtree
    _rmtree_safe_fd(fd, path, onerror)
  File "/projects/bamo6610/software/anaconda/env/openff-sage/lib/python3.9/shutil.py", line 690, in _rmtree_safe_fd
    onerror(os.unlink, fullname, sys.exc_info())
  File "/projects/bamo6610/software/anaconda/env/openff-sage/lib/python3.9/shutil.py", line 688, in _rmtree_safe_fd
    os.unlink(entry.name, dir_fd=topfd)
OSError: [Errno 16] Device or resource busy: '.nfs00000000037d6d5e000009fe'
Warning: Cannot perform Hydrogen sampling with GPU-Omega: GPU-Omega disabled.
Traceback (most recent call last):
  File "/projects/bamo6610/software/anaconda/env/openff-sage/lib/python3.9/multiprocessing/process.py", line 315, in _bootstrap
    self.run()
  File "/projects/bamo6610/software/anaconda/env/openff-sage/lib/python3.9/multiprocessing/process.py", line 108, in run
    self._target(*self._args, **self._kwargs)
  File "/projects/bamo6610/software/anaconda/env/openff-sage/lib/python3.9/multiprocessing/managers.py", line 591, in _run_server
    server.serve_forever()
  File "/projects/bamo6610/software/anaconda/env/openff-sage/lib/python3.9/multiprocessing/managers.py", line 184, in serve_forever
    sys.exit(0)
SystemExit: 0

During handling of the above exception, another exception occurred:

Traceback (most recent call last):
  File "/projects/bamo6610/software/anaconda/env/openff-sage/lib/python3.9/multiprocessing/util.py", line 300, in _run_finalizers
    finalizer()
  File "/projects/bamo6610/software/anaconda/env/openff-sage/lib/python3.9/multiprocessing/util.py", line 224, in __call__
    res = self._callback(*self._args, **self._kwargs)
  File "/projects/bamo6610/software/anaconda/env/openff-sage/lib/python3.9/multiprocessing/util.py", line 133, in _remove_temp_dir
    rmtree(tempdir)
  File "/projects/bamo6610/software/anaconda/env/openff-sage/lib/python3.9/shutil.py", line 734, in rmtree
    _rmtree_safe_fd(fd, path, onerror)
  File "/projects/bamo6610/software/anaconda/env/openff-sage/lib/python3.9/shutil.py", line 690, in _rmtree_safe_fd
    onerror(os.unlink, fullname, sys.exc_info())
  File "/projects/bamo6610/software/anaconda/env/openff-sage/lib/python3.9/shutil.py", line 688, in _rmtree_safe_fd
    os.unlink(entry.name, dir_fd=topfd)
OSError: [Errno 16] Device or resource busy: '.nfs00000000037d6d60000009ff'
Traceback (most recent call last):
  File "/projects/bamo6610/software/anaconda/env/openff-sage/lib/python3.9/multiprocessing/process.py", line 315, in _bootstrap
    self.run()
  File "/projects/bamo6610/software/anaconda/env/openff-sage/lib/python3.9/multiprocessing/process.py", line 108, in run
    self._target(*self._args, **self._kwargs)
  File "/projects/bamo6610/software/anaconda/env/openff-sage/lib/python3.9/multiprocessing/managers.py", line 591, in _run_server
    server.serve_forever()
  File "/projects/bamo6610/software/anaconda/env/openff-sage/lib/python3.9/multiprocessing/managers.py", line 184, in serve_forever
    sys.exit(0)
SystemExit: 0

During handling of the above exception, another exception occurred:

Traceback (most recent call last):
  File "/projects/bamo6610/software/anaconda/env/openff-sage/lib/python3.9/multiprocessing/util.py", line 300, in _run_finalizers
    finalizer()
  File "/projects/bamo6610/software/anaconda/env/openff-sage/lib/python3.9/multiprocessing/util.py", line 224, in __call__
    res = self._callback(*self._args, **self._kwargs)
  File "/projects/bamo6610/software/anaconda/env/openff-sage/lib/python3.9/multiprocessing/util.py", line 133, in _remove_temp_dir
    rmtree(tempdir)
  File "/projects/bamo6610/software/anaconda/env/openff-sage/lib/python3.9/shutil.py", line 734, in rmtree
    _rmtree_safe_fd(fd, path, onerror)
  File "/projects/bamo6610/software/anaconda/env/openff-sage/lib/python3.9/shutil.py", line 690, in _rmtree_safe_fd
    onerror(os.unlink, fullname, sys.exc_info())
  File "/projects/bamo6610/software/anaconda/env/openff-sage/lib/python3.9/shutil.py", line 688, in _rmtree_safe_fd
    os.unlink(entry.name, dir_fd=topfd)
OSError: [Errno 16] Device or resource busy: '.nfs00000000037d6d6500000a00'
Warning: importing 'simtk.openmm' is deprecated.  Import 'openmm' instead.
2024-08-09 10:39:25,770: Setting CUDA platform to use precision model 'mixed'.
2024-08-09 10:39:25,829: Reading phase solvent1
2024-08-09 10:39:26,293: WARNING - openmmtools.multistate.multistatesampler - Warning: The openmmtools.multistate API is experimental and may change in future releases
2024-08-09 10:39:26,334: Reading phase solvent2
2024-08-09 10:39:26,347: WARNING - openmmtools.multistate.multistatesampler - Warning: The openmmtools.multistate API is experimental and may change in future releases
2024-08-09 10:39:27,400: Protocol failed to execute: dd5890c428a94c58a122ef64a8659bdb|run_solvation_yank
2024-08-09 10:39:27,400: Protocol failed to execute: dd5890c428a94c58a122ef64a8659bdb|conditional_group
Traceback (most recent call last):
  File "/projects/bamo6610/software/anaconda/env/openff-sage/lib/python3.9/multiprocessing/process.py", line 315, in _bootstrap
    self.run()
  File "/projects/bamo6610/software/anaconda/env/openff-sage/lib/python3.9/multiprocessing/process.py", line 108, in run
    self._target(*self._args, **self._kwargs)
  File "/projects/bamo6610/software/anaconda/env/openff-sage/lib/python3.9/multiprocessing/managers.py", line 591, in _run_server
    server.serve_forever()
  File "/projects/bamo6610/software/anaconda/env/openff-sage/lib/python3.9/multiprocessing/managers.py", line 184, in serve_forever
    sys.exit(0)
SystemExit: 0

During handling of the above exception, another exception occurred:

Traceback (most recent call last):
  File "/projects/bamo6610/software/anaconda/env/openff-sage/lib/python3.9/multiprocessing/util.py", line 300, in _run_finalizers
    finalizer()
  File "/projects/bamo6610/software/anaconda/env/openff-sage/lib/python3.9/multiprocessing/util.py", line 224, in __call__
    res = self._callback(*self._args, **self._kwargs)
  File "/projects/bamo6610/software/anaconda/env/openff-sage/lib/python3.9/multiprocessing/util.py", line 133, in _remove_temp_dir
    rmtree(tempdir)
  File "/projects/bamo6610/software/anaconda/env/openff-sage/lib/python3.9/shutil.py", line 734, in rmtree
    _rmtree_safe_fd(fd, path, onerror)
  File "/projects/bamo6610/software/anaconda/env/openff-sage/lib/python3.9/shutil.py", line 690, in _rmtree_safe_fd
    onerror(os.unlink, fullname, sys.exc_info())
  File "/projects/bamo6610/software/anaconda/env/openff-sage/lib/python3.9/shutil.py", line 688, in _rmtree_safe_fd
    os.unlink(entry.name, dir_fd=topfd)
OSError: [Errno 16] Device or resource busy: '.nfs00000000037d6d6600000a01'
Warning: Cannot perform Hydrogen sampling with GPU-Omega: GPU-Omega disabled.
Traceback (most recent call last):
  File "/projects/bamo6610/software/anaconda/env/openff-sage/lib/python3.9/multiprocessing/process.py", line 315, in _bootstrap
    self.run()
  File "/projects/bamo6610/software/anaconda/env/openff-sage/lib/python3.9/multiprocessing/process.py", line 108, in run
    self._target(*self._args, **self._kwargs)
  File "/projects/bamo6610/software/anaconda/env/openff-sage/lib/python3.9/multiprocessing/managers.py", line 591, in _run_server
    server.serve_forever()
  File "/projects/bamo6610/software/anaconda/env/openff-sage/lib/python3.9/multiprocessing/managers.py", line 184, in serve_forever
    sys.exit(0)
SystemExit: 0

During handling of the above exception, another exception occurred:

Traceback (most recent call last):
  File "/projects/bamo6610/software/anaconda/env/openff-sage/lib/python3.9/multiprocessing/util.py", line 300, in _run_finalizers
    finalizer()
  File "/projects/bamo6610/software/anaconda/env/openff-sage/lib/python3.9/multiprocessing/util.py", line 224, in __call__
    res = self._callback(*self._args, **self._kwargs)
  File "/projects/bamo6610/software/anaconda/env/openff-sage/lib/python3.9/multiprocessing/util.py", line 133, in _remove_temp_dir
    rmtree(tempdir)
  File "/projects/bamo6610/software/anaconda/env/openff-sage/lib/python3.9/shutil.py", line 734, in rmtree
    _rmtree_safe_fd(fd, path, onerror)
  File "/projects/bamo6610/software/anaconda/env/openff-sage/lib/python3.9/shutil.py", line 690, in _rmtree_safe_fd
    onerror(os.unlink, fullname, sys.exc_info())
  File "/projects/bamo6610/software/anaconda/env/openff-sage/lib/python3.9/shutil.py", line 688, in _rmtree_safe_fd
    os.unlink(entry.name, dir_fd=topfd)
OSError: [Errno 16] Device or resource busy: '.nfs00000000038d759d00000a02'
Traceback (most recent call last):
  File "/projects/bamo6610/software/anaconda/env/openff-sage/lib/python3.9/multiprocessing/process.py", line 315, in _bootstrap
    self.run()
  File "/projects/bamo6610/software/anaconda/env/openff-sage/lib/python3.9/multiprocessing/process.py", line 108, in run
    self._target(*self._args, **self._kwargs)
  File "/projects/bamo6610/software/anaconda/env/openff-sage/lib/python3.9/multiprocessing/managers.py", line 591, in _run_server
    server.serve_forever()
  File "/projects/bamo6610/software/anaconda/env/openff-sage/lib/python3.9/multiprocessing/managers.py", line 184, in serve_forever
    sys.exit(0)
SystemExit: 0

During handling of the above exception, another exception occurred:

Traceback (most recent call last):
  File "/projects/bamo6610/software/anaconda/env/openff-sage/lib/python3.9/multiprocessing/util.py", line 300, in _run_finalizers
    finalizer()
  File "/projects/bamo6610/software/anaconda/env/openff-sage/lib/python3.9/multiprocessing/util.py", line 224, in __call__
    res = self._callback(*self._args, **self._kwargs)
  File "/projects/bamo6610/software/anaconda/env/openff-sage/lib/python3.9/multiprocessing/util.py", line 133, in _remove_temp_dir
    rmtree(tempdir)
  File "/projects/bamo6610/software/anaconda/env/openff-sage/lib/python3.9/shutil.py", line 734, in rmtree
    _rmtree_safe_fd(fd, path, onerror)
  File "/projects/bamo6610/software/anaconda/env/openff-sage/lib/python3.9/shutil.py", line 690, in _rmtree_safe_fd
    onerror(os.unlink, fullname, sys.exc_info())
  File "/projects/bamo6610/software/anaconda/env/openff-sage/lib/python3.9/shutil.py", line 688, in _rmtree_safe_fd
    os.unlink(entry.name, dir_fd=topfd)
OSError: [Errno 16] Device or resource busy: '.nfs00000000038d75a100000a03'
Warning: Cannot perform Hydrogen sampling with GPU-Omega: GPU-Omega disabled.
Traceback (most recent call last):
  File "/projects/bamo6610/software/anaconda/env/openff-sage/lib/python3.9/multiprocessing/process.py", line 315, in _bootstrap
    self.run()
  File "/projects/bamo6610/software/anaconda/env/openff-sage/lib/python3.9/multiprocessing/process.py", line 108, in run
    self._target(*self._args, **self._kwargs)
  File "/projects/bamo6610/software/anaconda/env/openff-sage/lib/python3.9/multiprocessing/managers.py", line 591, in _run_server
    server.serve_forever()
  File "/projects/bamo6610/software/anaconda/env/openff-sage/lib/python3.9/multiprocessing/managers.py", line 184, in serve_forever
    sys.exit(0)
SystemExit: 0

During handling of the above exception, another exception occurred:

Traceback (most recent call last):
  File "/projects/bamo6610/software/anaconda/env/openff-sage/lib/python3.9/multiprocessing/util.py", line 300, in _run_finalizers
    finalizer()
  File "/projects/bamo6610/software/anaconda/env/openff-sage/lib/python3.9/multiprocessing/util.py", line 224, in __call__
    res = self._callback(*self._args, **self._kwargs)
  File "/projects/bamo6610/software/anaconda/env/openff-sage/lib/python3.9/multiprocessing/util.py", line 133, in _remove_temp_dir
    rmtree(tempdir)
  File "/projects/bamo6610/software/anaconda/env/openff-sage/lib/python3.9/shutil.py", line 734, in rmtree
    _rmtree_safe_fd(fd, path, onerror)
  File "/projects/bamo6610/software/anaconda/env/openff-sage/lib/python3.9/shutil.py", line 690, in _rmtree_safe_fd
    onerror(os.unlink, fullname, sys.exc_info())
  File "/projects/bamo6610/software/anaconda/env/openff-sage/lib/python3.9/shutil.py", line 688, in _rmtree_safe_fd
    os.unlink(entry.name, dir_fd=topfd)
OSError: [Errno 16] Device or resource busy: '.nfs00000000038d75a300000a04'
Traceback (most recent call last):
  File "/projects/bamo6610/software/anaconda/env/openff-sage/lib/python3.9/multiprocessing/process.py", line 315, in _bootstrap
    self.run()
  File "/projects/bamo6610/software/anaconda/env/openff-sage/lib/python3.9/multiprocessing/process.py", line 108, in run
    self._target(*self._args, **self._kwargs)
  File "/projects/bamo6610/software/anaconda/env/openff-sage/lib/python3.9/multiprocessing/managers.py", line 591, in _run_server
    server.serve_forever()
  File "/projects/bamo6610/software/anaconda/env/openff-sage/lib/python3.9/multiprocessing/managers.py", line 184, in serve_forever
    sys.exit(0)
SystemExit: 0

During handling of the above exception, another exception occurred:

Traceback (most recent call last):
  File "/projects/bamo6610/software/anaconda/env/openff-sage/lib/python3.9/multiprocessing/util.py", line 300, in _run_finalizers
    finalizer()
  File "/projects/bamo6610/software/anaconda/env/openff-sage/lib/python3.9/multiprocessing/util.py", line 224, in __call__
    res = self._callback(*self._args, **self._kwargs)
  File "/projects/bamo6610/software/anaconda/env/openff-sage/lib/python3.9/multiprocessing/util.py", line 133, in _remove_temp_dir
    rmtree(tempdir)
  File "/projects/bamo6610/software/anaconda/env/openff-sage/lib/python3.9/shutil.py", line 734, in rmtree
    _rmtree_safe_fd(fd, path, onerror)
  File "/projects/bamo6610/software/anaconda/env/openff-sage/lib/python3.9/shutil.py", line 690, in _rmtree_safe_fd
    onerror(os.unlink, fullname, sys.exc_info())
  File "/projects/bamo6610/software/anaconda/env/openff-sage/lib/python3.9/shutil.py", line 688, in _rmtree_safe_fd
    os.unlink(entry.name, dir_fd=topfd)
OSError: [Errno 16] Device or resource busy: '.nfs00000000038d75a700000a05'
Warning: Cannot perform Hydrogen sampling with GPU-Omega: GPU-Omega disabled.
Traceback (most recent call last):
  File "/projects/bamo6610/software/anaconda/env/openff-sage/lib/python3.9/multiprocessing/process.py", line 315, in _bootstrap
    self.run()
  File "/projects/bamo6610/software/anaconda/env/openff-sage/lib/python3.9/multiprocessing/process.py", line 108, in run
    self._target(*self._args, **self._kwargs)
  File "/projects/bamo6610/software/anaconda/env/openff-sage/lib/python3.9/multiprocessing/managers.py", line 591, in _run_server
    server.serve_forever()
  File "/projects/bamo6610/software/anaconda/env/openff-sage/lib/python3.9/multiprocessing/managers.py", line 184, in serve_forever
    sys.exit(0)
SystemExit: 0

During handling of the above exception, another exception occurred:

Traceback (most recent call last):
  File "/projects/bamo6610/software/anaconda/env/openff-sage/lib/python3.9/multiprocessing/util.py", line 300, in _run_finalizers
    finalizer()
  File "/projects/bamo6610/software/anaconda/env/openff-sage/lib/python3.9/multiprocessing/util.py", line 224, in __call__
    res = self._callback(*self._args, **self._kwargs)
  File "/projects/bamo6610/software/anaconda/env/openff-sage/lib/python3.9/multiprocessing/util.py", line 133, in _remove_temp_dir
    rmtree(tempdir)
  File "/projects/bamo6610/software/anaconda/env/openff-sage/lib/python3.9/shutil.py", line 734, in rmtree
    _rmtree_safe_fd(fd, path, onerror)
  File "/projects/bamo6610/software/anaconda/env/openff-sage/lib/python3.9/shutil.py", line 690, in _rmtree_safe_fd
    onerror(os.unlink, fullname, sys.exc_info())
  File "/projects/bamo6610/software/anaconda/env/openff-sage/lib/python3.9/shutil.py", line 688, in _rmtree_safe_fd
    os.unlink(entry.name, dir_fd=topfd)
OSError: [Errno 16] Device or resource busy: '.nfs00000000038d75a900000a06'
Traceback (most recent call last):
  File "/projects/bamo6610/software/anaconda/env/openff-sage/lib/python3.9/multiprocessing/process.py", line 315, in _bootstrap
    self.run()
  File "/projects/bamo6610/software/anaconda/env/openff-sage/lib/python3.9/multiprocessing/process.py", line 108, in run
    self._target(*self._args, **self._kwargs)
  File "/projects/bamo6610/software/anaconda/env/openff-sage/lib/python3.9/multiprocessing/managers.py", line 591, in _run_server
    server.serve_forever()
  File "/projects/bamo6610/software/anaconda/env/openff-sage/lib/python3.9/multiprocessing/managers.py", line 184, in serve_forever
    sys.exit(0)
SystemExit: 0

During handling of the above exception, another exception occurred:

Traceback (most recent call last):
  File "/projects/bamo6610/software/anaconda/env/openff-sage/lib/python3.9/multiprocessing/util.py", line 300, in _run_finalizers
    finalizer()
  File "/projects/bamo6610/software/anaconda/env/openff-sage/lib/python3.9/multiprocessing/util.py", line 224, in __call__
    res = self._callback(*self._args, **self._kwargs)
  File "/projects/bamo6610/software/anaconda/env/openff-sage/lib/python3.9/multiprocessing/util.py", line 133, in _remove_temp_dir
    rmtree(tempdir)
  File "/projects/bamo6610/software/anaconda/env/openff-sage/lib/python3.9/shutil.py", line 734, in rmtree
    _rmtree_safe_fd(fd, path, onerror)
  File "/projects/bamo6610/software/anaconda/env/openff-sage/lib/python3.9/shutil.py", line 690, in _rmtree_safe_fd
    onerror(os.unlink, fullname, sys.exc_info())
  File "/projects/bamo6610/software/anaconda/env/openff-sage/lib/python3.9/shutil.py", line 688, in _rmtree_safe_fd
    os.unlink(entry.name, dir_fd=topfd)
OSError: [Errno 16] Device or resource busy: '.nfs00000000032d429800000a07'
Warning: Cannot perform Hydrogen sampling with GPU-Omega: GPU-Omega disabled.
Traceback (most recent call last):
  File "/projects/bamo6610/software/anaconda/env/openff-sage/lib/python3.9/multiprocessing/process.py", line 315, in _bootstrap
    self.run()
  File "/projects/bamo6610/software/anaconda/env/openff-sage/lib/python3.9/multiprocessing/process.py", line 108, in run
    self._target(*self._args, **self._kwargs)
  File "/projects/bamo6610/software/anaconda/env/openff-sage/lib/python3.9/multiprocessing/managers.py", line 591, in _run_server
    server.serve_forever()
  File "/projects/bamo6610/software/anaconda/env/openff-sage/lib/python3.9/multiprocessing/managers.py", line 184, in serve_forever
    sys.exit(0)
SystemExit: 0

During handling of the above exception, another exception occurred:

Traceback (most recent call last):
  File "/projects/bamo6610/software/anaconda/env/openff-sage/lib/python3.9/multiprocessing/util.py", line 300, in _run_finalizers
    finalizer()
  File "/projects/bamo6610/software/anaconda/env/openff-sage/lib/python3.9/multiprocessing/util.py", line 224, in __call__
    res = self._callback(*self._args, **self._kwargs)
  File "/projects/bamo6610/software/anaconda/env/openff-sage/lib/python3.9/multiprocessing/util.py", line 133, in _remove_temp_dir
    rmtree(tempdir)
  File "/projects/bamo6610/software/anaconda/env/openff-sage/lib/python3.9/shutil.py", line 734, in rmtree
    _rmtree_safe_fd(fd, path, onerror)
  File "/projects/bamo6610/software/anaconda/env/openff-sage/lib/python3.9/shutil.py", line 690, in _rmtree_safe_fd
    onerror(os.unlink, fullname, sys.exc_info())
  File "/projects/bamo6610/software/anaconda/env/openff-sage/lib/python3.9/shutil.py", line 688, in _rmtree_safe_fd
    os.unlink(entry.name, dir_fd=topfd)
OSError: [Errno 16] Device or resource busy: '.nfs00000000038d75c500000a08'
Warning: Cannot perform Hydrogen sampling with GPU-Omega: GPU-Omega disabled.
Traceback (most recent call last):
  File "/projects/bamo6610/software/anaconda/env/openff-sage/lib/python3.9/multiprocessing/process.py", line 315, in _bootstrap
    self.run()
  File "/projects/bamo6610/software/anaconda/env/openff-sage/lib/python3.9/multiprocessing/process.py", line 108, in run
    self._target(*self._args, **self._kwargs)
  File "/projects/bamo6610/software/anaconda/env/openff-sage/lib/python3.9/multiprocessing/managers.py", line 591, in _run_server
    server.serve_forever()
  File "/projects/bamo6610/software/anaconda/env/openff-sage/lib/python3.9/multiprocessing/managers.py", line 184, in serve_forever
    sys.exit(0)
SystemExit: 0

During handling of the above exception, another exception occurred:

Traceback (most recent call last):
  File "/projects/bamo6610/software/anaconda/env/openff-sage/lib/python3.9/multiprocessing/util.py", line 300, in _run_finalizers
    finalizer()
  File "/projects/bamo6610/software/anaconda/env/openff-sage/lib/python3.9/multiprocessing/util.py", line 224, in __call__
    res = self._callback(*self._args, **self._kwargs)
  File "/projects/bamo6610/software/anaconda/env/openff-sage/lib/python3.9/multiprocessing/util.py", line 133, in _remove_temp_dir
    rmtree(tempdir)
  File "/projects/bamo6610/software/anaconda/env/openff-sage/lib/python3.9/shutil.py", line 734, in rmtree
    _rmtree_safe_fd(fd, path, onerror)
  File "/projects/bamo6610/software/anaconda/env/openff-sage/lib/python3.9/shutil.py", line 690, in _rmtree_safe_fd
    onerror(os.unlink, fullname, sys.exc_info())
  File "/projects/bamo6610/software/anaconda/env/openff-sage/lib/python3.9/shutil.py", line 688, in _rmtree_safe_fd
    os.unlink(entry.name, dir_fd=topfd)
OSError: [Errno 16] Device or resource busy: '.nfs00000000037d6d3500000a09'
Traceback (most recent call last):
  File "/projects/bamo6610/software/anaconda/env/openff-sage/lib/python3.9/multiprocessing/process.py", line 315, in _bootstrap
    self.run()
  File "/projects/bamo6610/software/anaconda/env/openff-sage/lib/python3.9/multiprocessing/process.py", line 108, in run
    self._target(*self._args, **self._kwargs)
  File "/projects/bamo6610/software/anaconda/env/openff-sage/lib/python3.9/multiprocessing/managers.py", line 591, in _run_server
    server.serve_forever()
  File "/projects/bamo6610/software/anaconda/env/openff-sage/lib/python3.9/multiprocessing/managers.py", line 184, in serve_forever
    sys.exit(0)
SystemExit: 0

During handling of the above exception, another exception occurred:

Traceback (most recent call last):
  File "/projects/bamo6610/software/anaconda/env/openff-sage/lib/python3.9/multiprocessing/util.py", line 300, in _run_finalizers
    finalizer()
  File "/projects/bamo6610/software/anaconda/env/openff-sage/lib/python3.9/multiprocessing/util.py", line 224, in __call__
    res = self._callback(*self._args, **self._kwargs)
  File "/projects/bamo6610/software/anaconda/env/openff-sage/lib/python3.9/multiprocessing/util.py", line 133, in _remove_temp_dir
    rmtree(tempdir)
  File "/projects/bamo6610/software/anaconda/env/openff-sage/lib/python3.9/shutil.py", line 734, in rmtree
    _rmtree_safe_fd(fd, path, onerror)
  File "/projects/bamo6610/software/anaconda/env/openff-sage/lib/python3.9/shutil.py", line 690, in _rmtree_safe_fd
    onerror(os.unlink, fullname, sys.exc_info())
  File "/projects/bamo6610/software/anaconda/env/openff-sage/lib/python3.9/shutil.py", line 688, in _rmtree_safe_fd
    os.unlink(entry.name, dir_fd=topfd)
OSError: [Errno 16] Device or resource busy: '.nfs00000000038d75cd00000a0a'
Warning: Cannot perform Hydrogen sampling with GPU-Omega: GPU-Omega disabled.
Traceback (most recent call last):
  File "/projects/bamo6610/software/anaconda/env/openff-sage/lib/python3.9/multiprocessing/process.py", line 315, in _bootstrap
    self.run()
  File "/projects/bamo6610/software/anaconda/env/openff-sage/lib/python3.9/multiprocessing/process.py", line 108, in run
    self._target(*self._args, **self._kwargs)
  File "/projects/bamo6610/software/anaconda/env/openff-sage/lib/python3.9/multiprocessing/managers.py", line 591, in _run_server
    server.serve_forever()
  File "/projects/bamo6610/software/anaconda/env/openff-sage/lib/python3.9/multiprocessing/managers.py", line 184, in serve_forever
    sys.exit(0)
SystemExit: 0

During handling of the above exception, another exception occurred:

Traceback (most recent call last):
  File "/projects/bamo6610/software/anaconda/env/openff-sage/lib/python3.9/multiprocessing/util.py", line 300, in _run_finalizers
    finalizer()
  File "/projects/bamo6610/software/anaconda/env/openff-sage/lib/python3.9/multiprocessing/util.py", line 224, in __call__
    res = self._callback(*self._args, **self._kwargs)
  File "/projects/bamo6610/software/anaconda/env/openff-sage/lib/python3.9/multiprocessing/util.py", line 133, in _remove_temp_dir
    rmtree(tempdir)
  File "/projects/bamo6610/software/anaconda/env/openff-sage/lib/python3.9/shutil.py", line 734, in rmtree
    _rmtree_safe_fd(fd, path, onerror)
  File "/projects/bamo6610/software/anaconda/env/openff-sage/lib/python3.9/shutil.py", line 690, in _rmtree_safe_fd
    onerror(os.unlink, fullname, sys.exc_info())
  File "/projects/bamo6610/software/anaconda/env/openff-sage/lib/python3.9/shutil.py", line 688, in _rmtree_safe_fd
    os.unlink(entry.name, dir_fd=topfd)
OSError: [Errno 16] Device or resource busy: '.nfs00000000038d75db00000a0b'
Traceback (most recent call last):
  File "/projects/bamo6610/software/anaconda/env/openff-sage/lib/python3.9/multiprocessing/process.py", line 315, in _bootstrap
    self.run()
  File "/projects/bamo6610/software/anaconda/env/openff-sage/lib/python3.9/multiprocessing/process.py", line 108, in run
    self._target(*self._args, **self._kwargs)
  File "/projects/bamo6610/software/anaconda/env/openff-sage/lib/python3.9/multiprocessing/managers.py", line 591, in _run_server
    server.serve_forever()
  File "/projects/bamo6610/software/anaconda/env/openff-sage/lib/python3.9/multiprocessing/managers.py", line 184, in serve_forever
    sys.exit(0)
SystemExit: 0

During handling of the above exception, another exception occurred:

Traceback (most recent call last):
  File "/projects/bamo6610/software/anaconda/env/openff-sage/lib/python3.9/multiprocessing/util.py", line 300, in _run_finalizers
    finalizer()
  File "/projects/bamo6610/software/anaconda/env/openff-sage/lib/python3.9/multiprocessing/util.py", line 224, in __call__
    res = self._callback(*self._args, **self._kwargs)
  File "/projects/bamo6610/software/anaconda/env/openff-sage/lib/python3.9/multiprocessing/util.py", line 133, in _remove_temp_dir
    rmtree(tempdir)
  File "/projects/bamo6610/software/anaconda/env/openff-sage/lib/python3.9/shutil.py", line 734, in rmtree
    _rmtree_safe_fd(fd, path, onerror)
  File "/projects/bamo6610/software/anaconda/env/openff-sage/lib/python3.9/shutil.py", line 690, in _rmtree_safe_fd
    onerror(os.unlink, fullname, sys.exc_info())
  File "/projects/bamo6610/software/anaconda/env/openff-sage/lib/python3.9/shutil.py", line 688, in _rmtree_safe_fd
    os.unlink(entry.name, dir_fd=topfd)
OSError: [Errno 16] Device or resource busy: '.nfs00000000032d42c800000a0c'
Traceback (most recent call last):
  File "/projects/bamo6610/software/anaconda/env/openff-sage/lib/python3.9/multiprocessing/process.py", line 315, in _bootstrap
    self.run()
  File "/projects/bamo6610/software/anaconda/env/openff-sage/lib/python3.9/multiprocessing/process.py", line 108, in run
    self._target(*self._args, **self._kwargs)
  File "/projects/bamo6610/software/anaconda/env/openff-sage/lib/python3.9/multiprocessing/managers.py", line 591, in _run_server
    server.serve_forever()
  File "/projects/bamo6610/software/anaconda/env/openff-sage/lib/python3.9/multiprocessing/managers.py", line 184, in serve_forever
    sys.exit(0)
SystemExit: 0

During handling of the above exception, another exception occurred:

Traceback (most recent call last):
  File "/projects/bamo6610/software/anaconda/env/openff-sage/lib/python3.9/multiprocessing/util.py", line 300, in _run_finalizers
    finalizer()
  File "/projects/bamo6610/software/anaconda/env/openff-sage/lib/python3.9/multiprocessing/util.py", line 224, in __call__
    res = self._callback(*self._args, **self._kwargs)
  File "/projects/bamo6610/software/anaconda/env/openff-sage/lib/python3.9/multiprocessing/util.py", line 133, in _remove_temp_dir
    rmtree(tempdir)
  File "/projects/bamo6610/software/anaconda/env/openff-sage/lib/python3.9/shutil.py", line 734, in rmtree
    _rmtree_safe_fd(fd, path, onerror)
  File "/projects/bamo6610/software/anaconda/env/openff-sage/lib/python3.9/shutil.py", line 690, in _rmtree_safe_fd
    onerror(os.unlink, fullname, sys.exc_info())
  File "/projects/bamo6610/software/anaconda/env/openff-sage/lib/python3.9/shutil.py", line 688, in _rmtree_safe_fd
    os.unlink(entry.name, dir_fd=topfd)
OSError: [Errno 16] Device or resource busy: '.nfs0000000003bd8f0c00000a0d'
Warning: importing 'simtk.openmm' is deprecated.  Import 'openmm' instead.
2024-08-09 10:40:15,580: Setting CUDA platform to use precision model 'mixed'.
2024-08-09 10:40:15,638: Reading phase solvent1
2024-08-09 10:40:16,099: WARNING - openmmtools.multistate.multistatesampler - Warning: The openmmtools.multistate API is experimental and may change in future releases
2024-08-09 10:40:16,128: Reading phase solvent2
2024-08-09 10:40:16,138: WARNING - openmmtools.multistate.multistatesampler - Warning: The openmmtools.multistate API is experimental and may change in future releases
2024-08-09 10:40:17,153: Protocol failed to execute: 53d890c5e444419da73c75a6c3e20413|run_solvation_yank
2024-08-09 10:40:17,153: Protocol failed to execute: 53d890c5e444419da73c75a6c3e20413|conditional_group
Traceback (most recent call last):
  File "/projects/bamo6610/software/anaconda/env/openff-sage/lib/python3.9/multiprocessing/process.py", line 315, in _bootstrap
    self.run()
  File "/projects/bamo6610/software/anaconda/env/openff-sage/lib/python3.9/multiprocessing/process.py", line 108, in run
    self._target(*self._args, **self._kwargs)
  File "/projects/bamo6610/software/anaconda/env/openff-sage/lib/python3.9/multiprocessing/managers.py", line 591, in _run_server
    server.serve_forever()
  File "/projects/bamo6610/software/anaconda/env/openff-sage/lib/python3.9/multiprocessing/managers.py", line 184, in serve_forever
    sys.exit(0)
SystemExit: 0

During handling of the above exception, another exception occurred:

Traceback (most recent call last):
  File "/projects/bamo6610/software/anaconda/env/openff-sage/lib/python3.9/multiprocessing/util.py", line 300, in _run_finalizers
    finalizer()
  File "/projects/bamo6610/software/anaconda/env/openff-sage/lib/python3.9/multiprocessing/util.py", line 224, in __call__
    res = self._callback(*self._args, **self._kwargs)
  File "/projects/bamo6610/software/anaconda/env/openff-sage/lib/python3.9/multiprocessing/util.py", line 133, in _remove_temp_dir
    rmtree(tempdir)
  File "/projects/bamo6610/software/anaconda/env/openff-sage/lib/python3.9/shutil.py", line 734, in rmtree
    _rmtree_safe_fd(fd, path, onerror)
  File "/projects/bamo6610/software/anaconda/env/openff-sage/lib/python3.9/shutil.py", line 690, in _rmtree_safe_fd
    onerror(os.unlink, fullname, sys.exc_info())
  File "/projects/bamo6610/software/anaconda/env/openff-sage/lib/python3.9/shutil.py", line 688, in _rmtree_safe_fd
    os.unlink(entry.name, dir_fd=topfd)
OSError: [Errno 16] Device or resource busy: '.nfs0000000003bd8f0f00000a0e'
Warning: Cannot perform Hydrogen sampling with GPU-Omega: GPU-Omega disabled.
Traceback (most recent call last):
  File "/projects/bamo6610/software/anaconda/env/openff-sage/lib/python3.9/multiprocessing/process.py", line 315, in _bootstrap
    self.run()
  File "/projects/bamo6610/software/anaconda/env/openff-sage/lib/python3.9/multiprocessing/process.py", line 108, in run
    self._target(*self._args, **self._kwargs)
  File "/projects/bamo6610/software/anaconda/env/openff-sage/lib/python3.9/multiprocessing/managers.py", line 591, in _run_server
    server.serve_forever()
  File "/projects/bamo6610/software/anaconda/env/openff-sage/lib/python3.9/multiprocessing/managers.py", line 184, in serve_forever
    sys.exit(0)
SystemExit: 0

During handling of the above exception, another exception occurred:

Traceback (most recent call last):
  File "/projects/bamo6610/software/anaconda/env/openff-sage/lib/python3.9/multiprocessing/util.py", line 300, in _run_finalizers
    finalizer()
  File "/projects/bamo6610/software/anaconda/env/openff-sage/lib/python3.9/multiprocessing/util.py", line 224, in __call__
    res = self._callback(*self._args, **self._kwargs)
  File "/projects/bamo6610/software/anaconda/env/openff-sage/lib/python3.9/multiprocessing/util.py", line 133, in _remove_temp_dir
    rmtree(tempdir)
  File "/projects/bamo6610/software/anaconda/env/openff-sage/lib/python3.9/shutil.py", line 734, in rmtree
    _rmtree_safe_fd(fd, path, onerror)
  File "/projects/bamo6610/software/anaconda/env/openff-sage/lib/python3.9/shutil.py", line 690, in _rmtree_safe_fd
    onerror(os.unlink, fullname, sys.exc_info())
  File "/projects/bamo6610/software/anaconda/env/openff-sage/lib/python3.9/shutil.py", line 688, in _rmtree_safe_fd
    os.unlink(entry.name, dir_fd=topfd)
OSError: [Errno 16] Device or resource busy: '.nfs0000000003bd8f3a00000a0f'
Traceback (most recent call last):
  File "/projects/bamo6610/software/anaconda/env/openff-sage/lib/python3.9/multiprocessing/process.py", line 315, in _bootstrap
    self.run()
  File "/projects/bamo6610/software/anaconda/env/openff-sage/lib/python3.9/multiprocessing/process.py", line 108, in run
    self._target(*self._args, **self._kwargs)
  File "/projects/bamo6610/software/anaconda/env/openff-sage/lib/python3.9/multiprocessing/managers.py", line 591, in _run_server
    server.serve_forever()
  File "/projects/bamo6610/software/anaconda/env/openff-sage/lib/python3.9/multiprocessing/managers.py", line 184, in serve_forever
    sys.exit(0)
SystemExit: 0

During handling of the above exception, another exception occurred:

Traceback (most recent call last):
  File "/projects/bamo6610/software/anaconda/env/openff-sage/lib/python3.9/multiprocessing/util.py", line 300, in _run_finalizers
    finalizer()
  File "/projects/bamo6610/software/anaconda/env/openff-sage/lib/python3.9/multiprocessing/util.py", line 224, in __call__
    res = self._callback(*self._args, **self._kwargs)
  File "/projects/bamo6610/software/anaconda/env/openff-sage/lib/python3.9/multiprocessing/util.py", line 133, in _remove_temp_dir
    rmtree(tempdir)
  File "/projects/bamo6610/software/anaconda/env/openff-sage/lib/python3.9/shutil.py", line 734, in rmtree
    _rmtree_safe_fd(fd, path, onerror)
  File "/projects/bamo6610/software/anaconda/env/openff-sage/lib/python3.9/shutil.py", line 690, in _rmtree_safe_fd
    onerror(os.unlink, fullname, sys.exc_info())
  File "/projects/bamo6610/software/anaconda/env/openff-sage/lib/python3.9/shutil.py", line 688, in _rmtree_safe_fd
    os.unlink(entry.name, dir_fd=topfd)
OSError: [Errno 16] Device or resource busy: '.nfs0000000003bd8f6800000a10'
Warning: Cannot perform Hydrogen sampling with GPU-Omega: GPU-Omega disabled.
Traceback (most recent call last):
  File "/projects/bamo6610/software/anaconda/env/openff-sage/lib/python3.9/multiprocessing/process.py", line 315, in _bootstrap
    self.run()
  File "/projects/bamo6610/software/anaconda/env/openff-sage/lib/python3.9/multiprocessing/process.py", line 108, in run
    self._target(*self._args, **self._kwargs)
  File "/projects/bamo6610/software/anaconda/env/openff-sage/lib/python3.9/multiprocessing/managers.py", line 591, in _run_server
    server.serve_forever()
  File "/projects/bamo6610/software/anaconda/env/openff-sage/lib/python3.9/multiprocessing/managers.py", line 184, in serve_forever
    sys.exit(0)
SystemExit: 0

During handling of the above exception, another exception occurred:

Traceback (most recent call last):
  File "/projects/bamo6610/software/anaconda/env/openff-sage/lib/python3.9/multiprocessing/util.py", line 300, in _run_finalizers
    finalizer()
  File "/projects/bamo6610/software/anaconda/env/openff-sage/lib/python3.9/multiprocessing/util.py", line 224, in __call__
    res = self._callback(*self._args, **self._kwargs)
  File "/projects/bamo6610/software/anaconda/env/openff-sage/lib/python3.9/multiprocessing/util.py", line 133, in _remove_temp_dir
    rmtree(tempdir)
  File "/projects/bamo6610/software/anaconda/env/openff-sage/lib/python3.9/shutil.py", line 734, in rmtree
    _rmtree_safe_fd(fd, path, onerror)
  File "/projects/bamo6610/software/anaconda/env/openff-sage/lib/python3.9/shutil.py", line 690, in _rmtree_safe_fd
    onerror(os.unlink, fullname, sys.exc_info())
  File "/projects/bamo6610/software/anaconda/env/openff-sage/lib/python3.9/shutil.py", line 688, in _rmtree_safe_fd
    os.unlink(entry.name, dir_fd=topfd)
OSError: [Errno 16] Device or resource busy: '.nfs0000000003bd8f0f00000a11'
Traceback (most recent call last):
  File "/projects/bamo6610/software/anaconda/env/openff-sage/lib/python3.9/multiprocessing/process.py", line 315, in _bootstrap
    self.run()
  File "/projects/bamo6610/software/anaconda/env/openff-sage/lib/python3.9/multiprocessing/process.py", line 108, in run
    self._target(*self._args, **self._kwargs)
  File "/projects/bamo6610/software/anaconda/env/openff-sage/lib/python3.9/multiprocessing/managers.py", line 591, in _run_server
    server.serve_forever()
  File "/projects/bamo6610/software/anaconda/env/openff-sage/lib/python3.9/multiprocessing/managers.py", line 184, in serve_forever
    sys.exit(0)
SystemExit: 0

During handling of the above exception, another exception occurred:

Traceback (most recent call last):
  File "/projects/bamo6610/software/anaconda/env/openff-sage/lib/python3.9/multiprocessing/util.py", line 300, in _run_finalizers
    finalizer()
  File "/projects/bamo6610/software/anaconda/env/openff-sage/lib/python3.9/multiprocessing/util.py", line 224, in __call__
    res = self._callback(*self._args, **self._kwargs)
  File "/projects/bamo6610/software/anaconda/env/openff-sage/lib/python3.9/multiprocessing/util.py", line 133, in _remove_temp_dir
    rmtree(tempdir)
  File "/projects/bamo6610/software/anaconda/env/openff-sage/lib/python3.9/shutil.py", line 734, in rmtree
    _rmtree_safe_fd(fd, path, onerror)
  File "/projects/bamo6610/software/anaconda/env/openff-sage/lib/python3.9/shutil.py", line 690, in _rmtree_safe_fd
    onerror(os.unlink, fullname, sys.exc_info())
  File "/projects/bamo6610/software/anaconda/env/openff-sage/lib/python3.9/shutil.py", line 688, in _rmtree_safe_fd
    os.unlink(entry.name, dir_fd=topfd)
OSError: [Errno 16] Device or resource busy: '.nfs0000000003bd8f7900000a12'
Traceback (most recent call last):
  File "/projects/bamo6610/software/anaconda/env/openff-sage/lib/python3.9/multiprocessing/process.py", line 315, in _bootstrap
    self.run()
  File "/projects/bamo6610/software/anaconda/env/openff-sage/lib/python3.9/multiprocessing/process.py", line 108, in run
    self._target(*self._args, **self._kwargs)
  File "/projects/bamo6610/software/anaconda/env/openff-sage/lib/python3.9/multiprocessing/managers.py", line 591, in _run_server
    server.serve_forever()
  File "/projects/bamo6610/software/anaconda/env/openff-sage/lib/python3.9/multiprocessing/managers.py", line 184, in serve_forever
    sys.exit(0)
SystemExit: 0

During handling of the above exception, another exception occurred:

Traceback (most recent call last):
  File "/projects/bamo6610/software/anaconda/env/openff-sage/lib/python3.9/multiprocessing/util.py", line 300, in _run_finalizers
    finalizer()
  File "/projects/bamo6610/software/anaconda/env/openff-sage/lib/python3.9/multiprocessing/util.py", line 224, in __call__
    res = self._callback(*self._args, **self._kwargs)
  File "/projects/bamo6610/software/anaconda/env/openff-sage/lib/python3.9/multiprocessing/util.py", line 133, in _remove_temp_dir
    rmtree(tempdir)
  File "/projects/bamo6610/software/anaconda/env/openff-sage/lib/python3.9/shutil.py", line 734, in rmtree
    _rmtree_safe_fd(fd, path, onerror)
  File "/projects/bamo6610/software/anaconda/env/openff-sage/lib/python3.9/shutil.py", line 690, in _rmtree_safe_fd
    onerror(os.unlink, fullname, sys.exc_info())
  File "/projects/bamo6610/software/anaconda/env/openff-sage/lib/python3.9/shutil.py", line 688, in _rmtree_safe_fd
    os.unlink(entry.name, dir_fd=topfd)
OSError: [Errno 16] Device or resource busy: '.nfs0000000003ad86ed00000a13'
Warning: Cannot perform Hydrogen sampling with GPU-Omega: GPU-Omega disabled.
Traceback (most recent call last):
  File "/projects/bamo6610/software/anaconda/env/openff-sage/lib/python3.9/multiprocessing/process.py", line 315, in _bootstrap
    self.run()
  File "/projects/bamo6610/software/anaconda/env/openff-sage/lib/python3.9/multiprocessing/process.py", line 108, in run
    self._target(*self._args, **self._kwargs)
  File "/projects/bamo6610/software/anaconda/env/openff-sage/lib/python3.9/multiprocessing/managers.py", line 591, in _run_server
    server.serve_forever()
  File "/projects/bamo6610/software/anaconda/env/openff-sage/lib/python3.9/multiprocessing/managers.py", line 184, in serve_forever
    sys.exit(0)
SystemExit: 0

During handling of the above exception, another exception occurred:

Traceback (most recent call last):
  File "/projects/bamo6610/software/anaconda/env/openff-sage/lib/python3.9/multiprocessing/util.py", line 300, in _run_finalizers
    finalizer()
  File "/projects/bamo6610/software/anaconda/env/openff-sage/lib/python3.9/multiprocessing/util.py", line 224, in __call__
    res = self._callback(*self._args, **self._kwargs)
  File "/projects/bamo6610/software/anaconda/env/openff-sage/lib/python3.9/multiprocessing/util.py", line 133, in _remove_temp_dir
    rmtree(tempdir)
  File "/projects/bamo6610/software/anaconda/env/openff-sage/lib/python3.9/shutil.py", line 734, in rmtree
    _rmtree_safe_fd(fd, path, onerror)
  File "/projects/bamo6610/software/anaconda/env/openff-sage/lib/python3.9/shutil.py", line 690, in _rmtree_safe_fd
    onerror(os.unlink, fullname, sys.exc_info())
  File "/projects/bamo6610/software/anaconda/env/openff-sage/lib/python3.9/shutil.py", line 688, in _rmtree_safe_fd
    os.unlink(entry.name, dir_fd=topfd)
OSError: [Errno 16] Device or resource busy: '.nfs0000000002cd0fd200000a14'
Traceback (most recent call last):
  File "/projects/bamo6610/software/anaconda/env/openff-sage/lib/python3.9/multiprocessing/process.py", line 315, in _bootstrap
    self.run()
  File "/projects/bamo6610/software/anaconda/env/openff-sage/lib/python3.9/multiprocessing/process.py", line 108, in run
    self._target(*self._args, **self._kwargs)
  File "/projects/bamo6610/software/anaconda/env/openff-sage/lib/python3.9/multiprocessing/managers.py", line 591, in _run_server
    server.serve_forever()
  File "/projects/bamo6610/software/anaconda/env/openff-sage/lib/python3.9/multiprocessing/managers.py", line 184, in serve_forever
    sys.exit(0)
SystemExit: 0

During handling of the above exception, another exception occurred:

Traceback (most recent call last):
  File "/projects/bamo6610/software/anaconda/env/openff-sage/lib/python3.9/multiprocessing/util.py", line 300, in _run_finalizers
    finalizer()
  File "/projects/bamo6610/software/anaconda/env/openff-sage/lib/python3.9/multiprocessing/util.py", line 224, in __call__
    res = self._callback(*self._args, **self._kwargs)
  File "/projects/bamo6610/software/anaconda/env/openff-sage/lib/python3.9/multiprocessing/util.py", line 133, in _remove_temp_dir
    rmtree(tempdir)
  File "/projects/bamo6610/software/anaconda/env/openff-sage/lib/python3.9/shutil.py", line 734, in rmtree
    _rmtree_safe_fd(fd, path, onerror)
  File "/projects/bamo6610/software/anaconda/env/openff-sage/lib/python3.9/shutil.py", line 690, in _rmtree_safe_fd
    onerror(os.unlink, fullname, sys.exc_info())
  File "/projects/bamo6610/software/anaconda/env/openff-sage/lib/python3.9/shutil.py", line 688, in _rmtree_safe_fd
    os.unlink(entry.name, dir_fd=topfd)
OSError: [Errno 16] Device or resource busy: '.nfs0000000003cd979300000a15'
Warning: Cannot perform Hydrogen sampling with GPU-Omega: GPU-Omega disabled.
Traceback (most recent call last):
  File "/projects/bamo6610/software/anaconda/env/openff-sage/lib/python3.9/multiprocessing/process.py", line 315, in _bootstrap
    self.run()
  File "/projects/bamo6610/software/anaconda/env/openff-sage/lib/python3.9/multiprocessing/process.py", line 108, in run
    self._target(*self._args, **self._kwargs)
  File "/projects/bamo6610/software/anaconda/env/openff-sage/lib/python3.9/multiprocessing/managers.py", line 591, in _run_server
    server.serve_forever()
  File "/projects/bamo6610/software/anaconda/env/openff-sage/lib/python3.9/multiprocessing/managers.py", line 184, in serve_forever
    sys.exit(0)
SystemExit: 0

During handling of the above exception, another exception occurred:

Traceback (most recent call last):
  File "/projects/bamo6610/software/anaconda/env/openff-sage/lib/python3.9/multiprocessing/util.py", line 300, in _run_finalizers
    finalizer()
  File "/projects/bamo6610/software/anaconda/env/openff-sage/lib/python3.9/multiprocessing/util.py", line 224, in __call__
    res = self._callback(*self._args, **self._kwargs)
  File "/projects/bamo6610/software/anaconda/env/openff-sage/lib/python3.9/multiprocessing/util.py", line 133, in _remove_temp_dir
    rmtree(tempdir)
  File "/projects/bamo6610/software/anaconda/env/openff-sage/lib/python3.9/shutil.py", line 734, in rmtree
    _rmtree_safe_fd(fd, path, onerror)
  File "/projects/bamo6610/software/anaconda/env/openff-sage/lib/python3.9/shutil.py", line 690, in _rmtree_safe_fd
    onerror(os.unlink, fullname, sys.exc_info())
  File "/projects/bamo6610/software/anaconda/env/openff-sage/lib/python3.9/shutil.py", line 688, in _rmtree_safe_fd
    os.unlink(entry.name, dir_fd=topfd)
OSError: [Errno 16] Device or resource busy: '.nfs0000000003dda07d00000a16'
Warning: importing 'simtk.openmm' is deprecated.  Import 'openmm' instead.
2024-08-09 10:41:04,404: Setting CUDA platform to use precision model 'mixed'.
2024-08-09 10:41:04,464: Reading phase solvent1
2024-08-09 10:41:04,929: WARNING - openmmtools.multistate.multistatesampler - Warning: The openmmtools.multistate API is experimental and may change in future releases
2024-08-09 10:41:04,958: Reading phase solvent2
2024-08-09 10:41:04,970: WARNING - openmmtools.multistate.multistatesampler - Warning: The openmmtools.multistate API is experimental and may change in future releases
2024-08-09 10:41:06,000: Protocol failed to execute: bf86b36b51d64cbf876cfab6644a1de0|run_solvation_yank
2024-08-09 10:41:06,000: Protocol failed to execute: bf86b36b51d64cbf876cfab6644a1de0|conditional_group
Traceback (most recent call last):
  File "/projects/bamo6610/software/anaconda/env/openff-sage/lib/python3.9/multiprocessing/process.py", line 315, in _bootstrap
    self.run()
  File "/projects/bamo6610/software/anaconda/env/openff-sage/lib/python3.9/multiprocessing/process.py", line 108, in run
    self._target(*self._args, **self._kwargs)
  File "/projects/bamo6610/software/anaconda/env/openff-sage/lib/python3.9/multiprocessing/managers.py", line 591, in _run_server
    server.serve_forever()
  File "/projects/bamo6610/software/anaconda/env/openff-sage/lib/python3.9/multiprocessing/managers.py", line 184, in serve_forever
    sys.exit(0)
SystemExit: 0

During handling of the above exception, another exception occurred:

Traceback (most recent call last):
  File "/projects/bamo6610/software/anaconda/env/openff-sage/lib/python3.9/multiprocessing/util.py", line 300, in _run_finalizers
    finalizer()
  File "/projects/bamo6610/software/anaconda/env/openff-sage/lib/python3.9/multiprocessing/util.py", line 224, in __call__
    res = self._callback(*self._args, **self._kwargs)
  File "/projects/bamo6610/software/anaconda/env/openff-sage/lib/python3.9/multiprocessing/util.py", line 133, in _remove_temp_dir
    rmtree(tempdir)
  File "/projects/bamo6610/software/anaconda/env/openff-sage/lib/python3.9/shutil.py", line 734, in rmtree
    _rmtree_safe_fd(fd, path, onerror)
  File "/projects/bamo6610/software/anaconda/env/openff-sage/lib/python3.9/shutil.py", line 690, in _rmtree_safe_fd
    onerror(os.unlink, fullname, sys.exc_info())
  File "/projects/bamo6610/software/anaconda/env/openff-sage/lib/python3.9/shutil.py", line 688, in _rmtree_safe_fd
    os.unlink(entry.name, dir_fd=topfd)
OSError: [Errno 16] Device or resource busy: '.nfs0000000003eda88100000a17'
Traceback (most recent call last):
  File "/projects/bamo6610/software/anaconda/env/openff-sage/lib/python3.9/multiprocessing/process.py", line 315, in _bootstrap
    self.run()
  File "/projects/bamo6610/software/anaconda/env/openff-sage/lib/python3.9/multiprocessing/process.py", line 108, in run
    self._target(*self._args, **self._kwargs)
  File "/projects/bamo6610/software/anaconda/env/openff-sage/lib/python3.9/multiprocessing/managers.py", line 591, in _run_server
    server.serve_forever()
  File "/projects/bamo6610/software/anaconda/env/openff-sage/lib/python3.9/multiprocessing/managers.py", line 184, in serve_forever
    sys.exit(0)
SystemExit: 0

During handling of the above exception, another exception occurred:

Traceback (most recent call last):
  File "/projects/bamo6610/software/anaconda/env/openff-sage/lib/python3.9/multiprocessing/util.py", line 300, in _run_finalizers
    finalizer()
  File "/projects/bamo6610/software/anaconda/env/openff-sage/lib/python3.9/multiprocessing/util.py", line 224, in __call__
    res = self._callback(*self._args, **self._kwargs)
  File "/projects/bamo6610/software/anaconda/env/openff-sage/lib/python3.9/multiprocessing/util.py", line 133, in _remove_temp_dir
    rmtree(tempdir)
  File "/projects/bamo6610/software/anaconda/env/openff-sage/lib/python3.9/shutil.py", line 734, in rmtree
    _rmtree_safe_fd(fd, path, onerror)
  File "/projects/bamo6610/software/anaconda/env/openff-sage/lib/python3.9/shutil.py", line 690, in _rmtree_safe_fd
    onerror(os.unlink, fullname, sys.exc_info())
  File "/projects/bamo6610/software/anaconda/env/openff-sage/lib/python3.9/shutil.py", line 688, in _rmtree_safe_fd
    os.unlink(entry.name, dir_fd=topfd)
OSError: [Errno 16] Device or resource busy: '.nfs0000000003eda8be00000a18'
Traceback (most recent call last):
  File "/projects/bamo6610/software/anaconda/env/openff-sage/lib/python3.9/multiprocessing/process.py", line 315, in _bootstrap
    self.run()
  File "/projects/bamo6610/software/anaconda/env/openff-sage/lib/python3.9/multiprocessing/process.py", line 108, in run
    self._target(*self._args, **self._kwargs)
  File "/projects/bamo6610/software/anaconda/env/openff-sage/lib/python3.9/multiprocessing/managers.py", line 591, in _run_server
    server.serve_forever()
  File "/projects/bamo6610/software/anaconda/env/openff-sage/lib/python3.9/multiprocessing/managers.py", line 184, in serve_forever
    sys.exit(0)
SystemExit: 0

During handling of the above exception, another exception occurred:

Traceback (most recent call last):
  File "/projects/bamo6610/software/anaconda/env/openff-sage/lib/python3.9/multiprocessing/util.py", line 300, in _run_finalizers
    finalizer()
  File "/projects/bamo6610/software/anaconda/env/openff-sage/lib/python3.9/multiprocessing/util.py", line 224, in __call__
    res = self._callback(*self._args, **self._kwargs)
  File "/projects/bamo6610/software/anaconda/env/openff-sage/lib/python3.9/multiprocessing/util.py", line 133, in _remove_temp_dir
    rmtree(tempdir)
  File "/projects/bamo6610/software/anaconda/env/openff-sage/lib/python3.9/shutil.py", line 734, in rmtree
    _rmtree_safe_fd(fd, path, onerror)
  File "/projects/bamo6610/software/anaconda/env/openff-sage/lib/python3.9/shutil.py", line 690, in _rmtree_safe_fd
    onerror(os.unlink, fullname, sys.exc_info())
  File "/projects/bamo6610/software/anaconda/env/openff-sage/lib/python3.9/shutil.py", line 688, in _rmtree_safe_fd
    os.unlink(entry.name, dir_fd=topfd)
OSError: [Errno 16] Device or resource busy: '.nfs0000000003eda8c000000a19'
Warning: Cannot perform Hydrogen sampling with GPU-Omega: GPU-Omega disabled.
Traceback (most recent call last):
  File "/projects/bamo6610/software/anaconda/env/openff-sage/lib/python3.9/multiprocessing/process.py", line 315, in _bootstrap
    self.run()
  File "/projects/bamo6610/software/anaconda/env/openff-sage/lib/python3.9/multiprocessing/process.py", line 108, in run
    self._target(*self._args, **self._kwargs)
  File "/projects/bamo6610/software/anaconda/env/openff-sage/lib/python3.9/multiprocessing/managers.py", line 591, in _run_server
    server.serve_forever()
  File "/projects/bamo6610/software/anaconda/env/openff-sage/lib/python3.9/multiprocessing/managers.py", line 184, in serve_forever
    sys.exit(0)
SystemExit: 0

During handling of the above exception, another exception occurred:

Traceback (most recent call last):
  File "/projects/bamo6610/software/anaconda/env/openff-sage/lib/python3.9/multiprocessing/util.py", line 300, in _run_finalizers
    finalizer()
  File "/projects/bamo6610/software/anaconda/env/openff-sage/lib/python3.9/multiprocessing/util.py", line 224, in __call__
    res = self._callback(*self._args, **self._kwargs)
  File "/projects/bamo6610/software/anaconda/env/openff-sage/lib/python3.9/multiprocessing/util.py", line 133, in _remove_temp_dir
    rmtree(tempdir)
  File "/projects/bamo6610/software/anaconda/env/openff-sage/lib/python3.9/shutil.py", line 734, in rmtree
    _rmtree_safe_fd(fd, path, onerror)
  File "/projects/bamo6610/software/anaconda/env/openff-sage/lib/python3.9/shutil.py", line 690, in _rmtree_safe_fd
    onerror(os.unlink, fullname, sys.exc_info())
  File "/projects/bamo6610/software/anaconda/env/openff-sage/lib/python3.9/shutil.py", line 688, in _rmtree_safe_fd
    os.unlink(entry.name, dir_fd=topfd)
OSError: [Errno 16] Device or resource busy: '.nfs0000000003dda01100000a1a'
Warning: Cannot perform Hydrogen sampling with GPU-Omega: GPU-Omega disabled.
Traceback (most recent call last):
  File "/projects/bamo6610/software/anaconda/env/openff-sage/lib/python3.9/multiprocessing/process.py", line 315, in _bootstrap
    self.run()
  File "/projects/bamo6610/software/anaconda/env/openff-sage/lib/python3.9/multiprocessing/process.py", line 108, in run
    self._target(*self._args, **self._kwargs)
  File "/projects/bamo6610/software/anaconda/env/openff-sage/lib/python3.9/multiprocessing/managers.py", line 591, in _run_server
    server.serve_forever()
  File "/projects/bamo6610/software/anaconda/env/openff-sage/lib/python3.9/multiprocessing/managers.py", line 184, in serve_forever
    sys.exit(0)
SystemExit: 0

During handling of the above exception, another exception occurred:

Traceback (most recent call last):
  File "/projects/bamo6610/software/anaconda/env/openff-sage/lib/python3.9/multiprocessing/util.py", line 300, in _run_finalizers
    finalizer()
  File "/projects/bamo6610/software/anaconda/env/openff-sage/lib/python3.9/multiprocessing/util.py", line 224, in __call__
    res = self._callback(*self._args, **self._kwargs)
  File "/projects/bamo6610/software/anaconda/env/openff-sage/lib/python3.9/multiprocessing/util.py", line 133, in _remove_temp_dir
    rmtree(tempdir)
  File "/projects/bamo6610/software/anaconda/env/openff-sage/lib/python3.9/shutil.py", line 734, in rmtree
    _rmtree_safe_fd(fd, path, onerror)
  File "/projects/bamo6610/software/anaconda/env/openff-sage/lib/python3.9/shutil.py", line 690, in _rmtree_safe_fd
    onerror(os.unlink, fullname, sys.exc_info())
  File "/projects/bamo6610/software/anaconda/env/openff-sage/lib/python3.9/shutil.py", line 688, in _rmtree_safe_fd
    os.unlink(entry.name, dir_fd=topfd)
OSError: [Errno 16] Device or resource busy: '.nfs0000000003eda8e000000a1b'
Traceback (most recent call last):
  File "/projects/bamo6610/software/anaconda/env/openff-sage/lib/python3.9/multiprocessing/process.py", line 315, in _bootstrap
    self.run()
  File "/projects/bamo6610/software/anaconda/env/openff-sage/lib/python3.9/multiprocessing/process.py", line 108, in run
    self._target(*self._args, **self._kwargs)
  File "/projects/bamo6610/software/anaconda/env/openff-sage/lib/python3.9/multiprocessing/managers.py", line 591, in _run_server
    server.serve_forever()
  File "/projects/bamo6610/software/anaconda/env/openff-sage/lib/python3.9/multiprocessing/managers.py", line 184, in serve_forever
    sys.exit(0)
SystemExit: 0

During handling of the above exception, another exception occurred:

Traceback (most recent call last):
  File "/projects/bamo6610/software/anaconda/env/openff-sage/lib/python3.9/multiprocessing/util.py", line 300, in _run_finalizers
    finalizer()
  File "/projects/bamo6610/software/anaconda/env/openff-sage/lib/python3.9/multiprocessing/util.py", line 224, in __call__
    res = self._callback(*self._args, **self._kwargs)
  File "/projects/bamo6610/software/anaconda/env/openff-sage/lib/python3.9/multiprocessing/util.py", line 133, in _remove_temp_dir
    rmtree(tempdir)
  File "/projects/bamo6610/software/anaconda/env/openff-sage/lib/python3.9/shutil.py", line 734, in rmtree
    _rmtree_safe_fd(fd, path, onerror)
  File "/projects/bamo6610/software/anaconda/env/openff-sage/lib/python3.9/shutil.py", line 690, in _rmtree_safe_fd
    onerror(os.unlink, fullname, sys.exc_info())
  File "/projects/bamo6610/software/anaconda/env/openff-sage/lib/python3.9/shutil.py", line 688, in _rmtree_safe_fd
    os.unlink(entry.name, dir_fd=topfd)
OSError: [Errno 16] Device or resource busy: '.nfs0000000003fdb10500000a1c'
Traceback (most recent call last):
  File "/projects/bamo6610/software/anaconda/env/openff-sage/lib/python3.9/multiprocessing/process.py", line 315, in _bootstrap
    self.run()
  File "/projects/bamo6610/software/anaconda/env/openff-sage/lib/python3.9/multiprocessing/process.py", line 108, in run
    self._target(*self._args, **self._kwargs)
  File "/projects/bamo6610/software/anaconda/env/openff-sage/lib/python3.9/multiprocessing/managers.py", line 591, in _run_server
    server.serve_forever()
  File "/projects/bamo6610/software/anaconda/env/openff-sage/lib/python3.9/multiprocessing/managers.py", line 184, in serve_forever
    sys.exit(0)
SystemExit: 0

During handling of the above exception, another exception occurred:

Traceback (most recent call last):
  File "/projects/bamo6610/software/anaconda/env/openff-sage/lib/python3.9/multiprocessing/util.py", line 300, in _run_finalizers
    finalizer()
  File "/projects/bamo6610/software/anaconda/env/openff-sage/lib/python3.9/multiprocessing/util.py", line 224, in __call__
    res = self._callback(*self._args, **self._kwargs)
  File "/projects/bamo6610/software/anaconda/env/openff-sage/lib/python3.9/multiprocessing/util.py", line 133, in _remove_temp_dir
    rmtree(tempdir)
  File "/projects/bamo6610/software/anaconda/env/openff-sage/lib/python3.9/shutil.py", line 734, in rmtree
    _rmtree_safe_fd(fd, path, onerror)
  File "/projects/bamo6610/software/anaconda/env/openff-sage/lib/python3.9/shutil.py", line 690, in _rmtree_safe_fd
    onerror(os.unlink, fullname, sys.exc_info())
  File "/projects/bamo6610/software/anaconda/env/openff-sage/lib/python3.9/shutil.py", line 688, in _rmtree_safe_fd
    os.unlink(entry.name, dir_fd=topfd)
OSError: [Errno 16] Device or resource busy: '.nfs0000000003dda06f00000a1d'
Warning: importing 'simtk.openmm' is deprecated.  Import 'openmm' instead.
2024-08-09 10:41:50,729: Setting CUDA platform to use precision model 'mixed'.
2024-08-09 10:41:50,789: Reading phase solvent1
2024-08-09 10:41:51,257: WARNING - openmmtools.multistate.multistatesampler - Warning: The openmmtools.multistate API is experimental and may change in future releases
2024-08-09 10:41:51,285: Reading phase solvent2
2024-08-09 10:41:51,296: WARNING - openmmtools.multistate.multistatesampler - Warning: The openmmtools.multistate API is experimental and may change in future releases
2024-08-09 10:41:52,305: Protocol failed to execute: 62c1a72652b14b5aa151bde41ad25a61|run_solvation_yank
2024-08-09 10:41:52,305: Protocol failed to execute: 62c1a72652b14b5aa151bde41ad25a61|conditional_group
Traceback (most recent call last):
  File "/projects/bamo6610/software/anaconda/env/openff-sage/lib/python3.9/multiprocessing/process.py", line 315, in _bootstrap
    self.run()
  File "/projects/bamo6610/software/anaconda/env/openff-sage/lib/python3.9/multiprocessing/process.py", line 108, in run
    self._target(*self._args, **self._kwargs)
  File "/projects/bamo6610/software/anaconda/env/openff-sage/lib/python3.9/multiprocessing/managers.py", line 591, in _run_server
    server.serve_forever()
  File "/projects/bamo6610/software/anaconda/env/openff-sage/lib/python3.9/multiprocessing/managers.py", line 184, in serve_forever
    sys.exit(0)
SystemExit: 0

During handling of the above exception, another exception occurred:

Traceback (most recent call last):
  File "/projects/bamo6610/software/anaconda/env/openff-sage/lib/python3.9/multiprocessing/util.py", line 300, in _run_finalizers
    finalizer()
  File "/projects/bamo6610/software/anaconda/env/openff-sage/lib/python3.9/multiprocessing/util.py", line 224, in __call__
    res = self._callback(*self._args, **self._kwargs)
  File "/projects/bamo6610/software/anaconda/env/openff-sage/lib/python3.9/multiprocessing/util.py", line 133, in _remove_temp_dir
    rmtree(tempdir)
  File "/projects/bamo6610/software/anaconda/env/openff-sage/lib/python3.9/shutil.py", line 734, in rmtree
    _rmtree_safe_fd(fd, path, onerror)
  File "/projects/bamo6610/software/anaconda/env/openff-sage/lib/python3.9/shutil.py", line 690, in _rmtree_safe_fd
    onerror(os.unlink, fullname, sys.exc_info())
  File "/projects/bamo6610/software/anaconda/env/openff-sage/lib/python3.9/shutil.py", line 688, in _rmtree_safe_fd
    os.unlink(entry.name, dir_fd=topfd)
OSError: [Errno 16] Device or resource busy: '.nfs0000000003cd97a100000a1e'
Traceback (most recent call last):
  File "/projects/bamo6610/software/anaconda/env/openff-sage/lib/python3.9/multiprocessing/process.py", line 315, in _bootstrap
    self.run()
  File "/projects/bamo6610/software/anaconda/env/openff-sage/lib/python3.9/multiprocessing/process.py", line 108, in run
    self._target(*self._args, **self._kwargs)
  File "/projects/bamo6610/software/anaconda/env/openff-sage/lib/python3.9/multiprocessing/managers.py", line 591, in _run_server
    server.serve_forever()
  File "/projects/bamo6610/software/anaconda/env/openff-sage/lib/python3.9/multiprocessing/managers.py", line 184, in serve_forever
    sys.exit(0)
SystemExit: 0

During handling of the above exception, another exception occurred:

Traceback (most recent call last):
  File "/projects/bamo6610/software/anaconda/env/openff-sage/lib/python3.9/multiprocessing/util.py", line 300, in _run_finalizers
    finalizer()
  File "/projects/bamo6610/software/anaconda/env/openff-sage/lib/python3.9/multiprocessing/util.py", line 224, in __call__
    res = self._callback(*self._args, **self._kwargs)
  File "/projects/bamo6610/software/anaconda/env/openff-sage/lib/python3.9/multiprocessing/util.py", line 133, in _remove_temp_dir
    rmtree(tempdir)
  File "/projects/bamo6610/software/anaconda/env/openff-sage/lib/python3.9/shutil.py", line 734, in rmtree
    _rmtree_safe_fd(fd, path, onerror)
  File "/projects/bamo6610/software/anaconda/env/openff-sage/lib/python3.9/shutil.py", line 690, in _rmtree_safe_fd
    onerror(os.unlink, fullname, sys.exc_info())
  File "/projects/bamo6610/software/anaconda/env/openff-sage/lib/python3.9/shutil.py", line 688, in _rmtree_safe_fd
    os.unlink(entry.name, dir_fd=topfd)
OSError: [Errno 16] Device or resource busy: '.nfs00000000037d6d5b00000a1f'
Traceback (most recent call last):
  File "/projects/bamo6610/software/anaconda/env/openff-sage/lib/python3.9/multiprocessing/process.py", line 315, in _bootstrap
    self.run()
  File "/projects/bamo6610/software/anaconda/env/openff-sage/lib/python3.9/multiprocessing/process.py", line 108, in run
    self._target(*self._args, **self._kwargs)
  File "/projects/bamo6610/software/anaconda/env/openff-sage/lib/python3.9/multiprocessing/managers.py", line 591, in _run_server
    server.serve_forever()
  File "/projects/bamo6610/software/anaconda/env/openff-sage/lib/python3.9/multiprocessing/managers.py", line 184, in serve_forever
    sys.exit(0)
SystemExit: 0

During handling of the above exception, another exception occurred:

Traceback (most recent call last):
  File "/projects/bamo6610/software/anaconda/env/openff-sage/lib/python3.9/multiprocessing/util.py", line 300, in _run_finalizers
    finalizer()
  File "/projects/bamo6610/software/anaconda/env/openff-sage/lib/python3.9/multiprocessing/util.py", line 224, in __call__
    res = self._callback(*self._args, **self._kwargs)
  File "/projects/bamo6610/software/anaconda/env/openff-sage/lib/python3.9/multiprocessing/util.py", line 133, in _remove_temp_dir
    rmtree(tempdir)
  File "/projects/bamo6610/software/anaconda/env/openff-sage/lib/python3.9/shutil.py", line 734, in rmtree
    _rmtree_safe_fd(fd, path, onerror)
  File "/projects/bamo6610/software/anaconda/env/openff-sage/lib/python3.9/shutil.py", line 690, in _rmtree_safe_fd
    onerror(os.unlink, fullname, sys.exc_info())
  File "/projects/bamo6610/software/anaconda/env/openff-sage/lib/python3.9/shutil.py", line 688, in _rmtree_safe_fd
    os.unlink(entry.name, dir_fd=topfd)
OSError: [Errno 16] Device or resource busy: '.nfs00000000040db9c500000a20'
Traceback (most recent call last):
  File "/projects/bamo6610/software/anaconda/env/openff-sage/lib/python3.9/multiprocessing/process.py", line 315, in _bootstrap
    self.run()
  File "/projects/bamo6610/software/anaconda/env/openff-sage/lib/python3.9/multiprocessing/process.py", line 108, in run
    self._target(*self._args, **self._kwargs)
  File "/projects/bamo6610/software/anaconda/env/openff-sage/lib/python3.9/multiprocessing/managers.py", line 591, in _run_server
    server.serve_forever()
  File "/projects/bamo6610/software/anaconda/env/openff-sage/lib/python3.9/multiprocessing/managers.py", line 184, in serve_forever
    sys.exit(0)
SystemExit: 0

During handling of the above exception, another exception occurred:

Traceback (most recent call last):
  File "/projects/bamo6610/software/anaconda/env/openff-sage/lib/python3.9/multiprocessing/util.py", line 300, in _run_finalizers
    finalizer()
  File "/projects/bamo6610/software/anaconda/env/openff-sage/lib/python3.9/multiprocessing/util.py", line 224, in __call__
    res = self._callback(*self._args, **self._kwargs)
  File "/projects/bamo6610/software/anaconda/env/openff-sage/lib/python3.9/multiprocessing/util.py", line 133, in _remove_temp_dir
    rmtree(tempdir)
  File "/projects/bamo6610/software/anaconda/env/openff-sage/lib/python3.9/shutil.py", line 734, in rmtree
    _rmtree_safe_fd(fd, path, onerror)
  File "/projects/bamo6610/software/anaconda/env/openff-sage/lib/python3.9/shutil.py", line 690, in _rmtree_safe_fd
    onerror(os.unlink, fullname, sys.exc_info())
  File "/projects/bamo6610/software/anaconda/env/openff-sage/lib/python3.9/shutil.py", line 688, in _rmtree_safe_fd
    os.unlink(entry.name, dir_fd=topfd)
OSError: [Errno 16] Device or resource busy: '.nfs00000000038d75db00000a21'
{
  "@type": "openff.evaluator.datasets.datasets.PhysicalPropertyDataSet",
  "properties": []
}
It finished
JobID           JobName    CPUTime    Elapsed 
------------ ---------- ---------- ---------- 
17579867     sys/dashb+   00:21:14   00:21:14 
17579867.ba+      batch   00:21:14   00:21:14 
17579867.ex+     extern   00:21:14   00:21:14 
17580656     sfe_test_+   00:05:30   00:05:30 
17580656.ba+      batch   00:05:30   00:05:30 
17580656.ex+     extern   00:05:30   00:05:30 
